Workbook

Sheet Start here
B1: Geotechnical News · Q4 2026
B2: Issue window Oct – Dec 2026 · generated 26 Oct 2026
B5: This workbook holds 150 stories from 3 daily digests, 24 Oct 2026 to 26 Oct 2026, in 8 themes and from 108 sources.
B7: What is in this workbook
B8: Dashboard → | C8: Key figures, the Top 10 stories, charts by theme, use, relevance and planning status, a theme × use heat map and a timeline. Choose what it shows with the yellow selectors at the top.
B9: Stories → | C9: Every story as a filterable Excel table, newest digest first; click a headline to open the article. The gold columns – Status, Assigned to and Editor notes – are for you to fill in. Further right: the Primary source to check the facts with, where each story happened (Country, Place) and the Developing story it belongs to. A headline from a non-English source is Claude's English translation; Original headline gives the publisher's own.
B10: By theme → | C10: A read-only reading view: one section per theme, best stories first. Collapse or expand sections with the − / + buttons in the left margin.
B11: Research → | C11: 31 new papers from geotechnical journals for the Academia-to-Industry pages, best rated for use in practice first, with why each matters and a link to the paper. Status and Editor notes work as in Stories.
B12: Events → | C12: The events calendar on 26 Oct 2026: 3 open deadlines (calls for papers, registration) with the days left, and 45 upcoming events (ISSMGE conferences, other conferences, courses and webinars), each linked to its website.
B13: Sources → | C13: The outlets that supplied stories: how many, average relevance, main theme and how many match the current Dashboard selection.
B15: Before you use a story
B16: 1 | C16: Treat the news item as a lead, not as your source.
B17: 2 | C17: Check the facts with the primary source: the authority, the project owner, the company's press release or the official report (“Check with”, where the news desk found it).
B18: 3 | C18: Write the piece in your own words, with your own angle: the magazine angle is a starting point.
B19: 4 | C19: Quote a sentence or two at most, in quotation marks, naming the publication and linking to it.
B20: 5 | C20: For images, use your own, the project's press-kit photos released for media use, or ask permission; never reuse a source's photos, figures or drawings.
B22: How to use the Dashboard selectors
B23: 1 | C23: Open the Dashboard. The yellow boxes at the top are selectors: Theme, Suggested use, Minimum relevance and Issue window.
B24: 2 | C24: Click a yellow box, then the ▼ arrow that appears beside it, and pick a value. Choose “All …” or “Any” to clear that selector.
B25: 3 | C25: The key figures, tables, charts, heat map and the Top 10 list recalculate at once. Headlines in the Top 10 open the article.
B26: 4 | C26: In Stories, set each story’s Status as you plan the issue. The Dashboard’s Planning status table and chart, and the PLANNED figure, count them straight away.
B27: 5 | C27: Filters in the Stories table (▼ in its header) only hide rows; the Dashboard follows the selectors. To list exactly what the Dashboard shows, filter the ‘In Dashboard selection’ column of Stories to ✓.
B29: Planning status (Stories › Status)
B30: To review | C30: New from the scan, not looked at yet (every story starts here)
B31: Shortlisted | C31: Worth considering for the issue
B32: Commissioned | C32: A writer or contributor has been asked to cover it
B33: Published | C33: Used in a published issue or newsletter
B34: Not used | C34: Reviewed and set aside
B36: Relevance scale (AI triage)
B37: 5 / 5 | C37: Rich geotechnical lesson or a major ground-related event
B38: 4 / 5 | C38: Strong ground-engineering content
B39: 3 / 5 | C39: Clear ground-engineering element, worth a brief
B40: 2 / 5 | C40: Weak link to geotechnics
B41: 1 / 5 | C41: Not really geotechnical
B42: – | C42: Shown as –. Not rated by AI: ranked on keyword matches only
B44: Jump to a theme (opens its section in By theme)
B45: Sustainability & the Energy Transition | C45: 4 stories · 1 rated 5 / 5 · 1 feature lead
B46: Digital Geotechnics | C46: 5 stories · 1 rated 5 / 5 · 2 feature leads
B47: Hazards & Resilience | C47: 53 stories · 13 rated 5 / 5 · 34 feature leads
B48: Ground Improvement & Innovation | C48: 2 stories · 2 rated 5 / 5 · 1 feature lead
...

Sheet Dashboard
B1: Geotechnical News · Q4 2026
B2: Issue window Oct – Dec 2026 · generated 26 Oct 2026
B4: THEME | G4: SUGGESTED USE | K4: MINIMUM RELEVANCE (OUT OF 5) | N4: ISSUE WINDOW | Q4: Tip: click a yellow box, then its ▼ arrow, to choose. Pick “All …” or “Any” to clear it. Everything below updates.
B5: All themes | G5: All uses | K5: Any | N5: All windows
B6: ="Showing "&Lists!$H$6&" of "&Lists!$H$4&" stories"&IF(Lists!$H$5," – no selector set."," for the selection above. Set every box back to All / Any to see everything.")
B8: =Lists!$H$6 | E8: =IF(Lists!$H$5,Lists!$H$3,COUNTIF(Lists!$K$2:$K$4,">0")) | H8: =COUNTIFS(Stories!$W$4:$W$153,1,Stories!$D$4:$D$153,5) | K8: =COUNTIFS(Stories!$W$4:$W$153,1,Stories!$E$4:$E$153,"Feature lead") | N8: =COUNTIFS(Stories!$W$4:$W$153,1,Stories!$F$4:$F$153,"Shortlisted")+COUNTIFS(Stories!$W$4:$W$153,1,Stories!$F$4:$F$153,"Commissioned")+COUNTIFS(Stories!$W$4:$W$153,1,Stories!$F$4:$F$153,"Published") | Q8: =COUNTIF(Sources!$C$4:$C$111,">0")
B9: STORIES | E9: =IF(Lists!$H$5,"DAILY DIGESTS","DIGESTS WITH MATCHES") | H9: RATED 5 / 5 | K9: FEATURE LEADS | N9: PLANNED | Q9: SOURCES
B10: ="of "&Lists!$H$4&" in this workbook" | E10: =IF(Lists!$H$5,"scans in this period","of "&Lists!$H$3&" scans in this period") | H10: ="rated 4 / 5: "&COUNTIFS(Stories!$W$4:$W$153,1,Stories!$D$4:$D$153,4) | K10: ="news briefs: "&COUNTIFS(Stories!$W$4:$W$153,1,Stories!$E$4:$E$153,"News brief") | N10: ="shortlisted or later · to review: "&COUNTIFS(Stories!$W$4:$W$153,1,Stories!$F$4:$F$153,"To review") | Q10: ="of 108 outlets in this workbook"
B12: Top 10 stories for this selection
B13: # | C13: Headline (click to open the article) | I13: Digest | J13: Theme | M13: Relevance | N13: Suggested use | P13: Source | R13: Story No. | S13: Status
B14: =IF(Lists!$O$2="","",1) | C14: =IF(Lists!$O$2="","No stories match this selection – choose “All …” or “Any” in a box above.",IF(AND(Lists!$P$2<>"",LEN(Lists!$P$2)<=255),HYPERLINK(Lists!$P$2,Lists!$Q$2),HYPERLINK("#'Stories'!B"&(Lists!$O$2+3),Lists!$Q$2))) | I14: =IF(Lists!$O$2="","",INDEX(Stories!$K$4:$K$153,Lists!$O$2)) | J14: =IF(Lists!$O$2="","",INDEX(Stories!$C$4:$C$153,Lists!$O$2)&"") | M14: =IF(Lists!$O$2="","",INDEX(Stories!$D$4:$D$153,Lists!$O$2)) | N14: =IF(Lists!$O$2="","",INDEX(Stories!$E$4:$E$153,Lists!$O$2)&"") | P14: =IF(Lists!$O$2="","",INDEX(Stories!$J$4:$J$153,Lists!$O$2)&"") | R14: =IF(Lists!$O$2="","",INDEX(Stories!$A$4:$A$153,Lists!$O$2)) | S14: =IF(Lists!$O$2="","",INDEX(Stories!$F$4:$F$153,Lists!$O$2)&"")
B15: =IF(Lists!$O$3="","",2) | C15: =IF(Lists!$O$3="","",IF(AND(Lists!$P$3<>"",LEN(Lists!$P$3)<=255),HYPERLINK(Lists!$P$3,Lists!$Q$3),HYPERLINK("#'Stories'!B"&(Lists!$O$3+3),Lists!$Q$3))) | I15: =IF(Lists!$O$3="","",INDEX(Stories!$K$4:$K$153,Lists!$O$3)) | J15: =IF(Lists!$O$3="","",INDEX(Stories!$C$4:$C$153,Lists!$O$3)&"") | M15: =IF(Lists!$O$3="","",INDEX(Stories!$D$4:$D$153,Lists!$O$3)) | N15: =IF(Lists!$O$3="","",INDEX(Stories!$E$4:$E$153,Lists!$O$3)&"") | P15: =IF(Lists!$O$3="","",INDEX(Stories!$J$4:$J$153,Lists!$O$3)&"") | R15: =IF(Lists!$O$3="","",INDEX(Stories!$A$4:$A$153,Lists!$O$3)) | S15: =IF(Lists!$O$3="","",INDEX(Stories!$F$4:$F$153,Lists!$O$3)&"")
B16: =IF(Lists!$O$4="","",3) | C16: =IF(Lists!$O$4="","",IF(AND(Lists!$P$4<>"",LEN(Lists!$P$4)<=255),HYPERLINK(Lists!$P$4,Lists!$Q$4),HYPERLINK("#'Stories'!B"&(Lists!$O$4+3),Lists!$Q$4))) | I16: =IF(Lists!$O$4="","",INDEX(Stories!$K$4:$K$153,Lists!$O$4)) | J16: =IF(Lists!$O$4="","",INDEX(Stories!$C$4:$C$153,Lists!$O$4)&"") | M16: =IF(Lists!$O$4="","",INDEX(Stories!$D$4:$D$153,Lists!$O$4)) | N16: =IF(Lists!$O$4="","",INDEX(Stories!$E$4:$E$153,Lists!$O$4)&"") | P16: =IF(Lists!$O$4="","",INDEX(Stories!$J$4:$J$153,Lists!$O$4)&"") | R16: =IF(Lists!$O$4="","",INDEX(Stories!$A$4:$A$153,Lists!$O$4)) | S16: =IF(Lists!$O$4="","",INDEX(Stories!$F$4:$F$153,Lists!$O$4)&"")
B17: =IF(Lists!$O$5="","",4) | C17: =IF(Lists!$O$5="","",IF(AND(Lists!$P$5<>"",LEN(Lists!$P$5)<=255),HYPERLINK(Lists!$P$5,Lists!$Q$5),HYPERLINK("#'Stories'!B"&(Lists!$O$5+3),Lists!$Q$5))) | I17: =IF(Lists!$O$5="","",INDEX(Stories!$K$4:$K$153,Lists!$O$5)) | J17: =IF(Lists!$O$5="","",INDEX(Stories!$C$4:$C$153,Lists!$O$5)&"") | M17: =IF(Lists!$O$5="","",INDEX(Stories!$D$4:$D$153,Lists!$O$5)) | N17: =IF(Lists!$O$5="","",INDEX(Stories!$E$4:$E$153,Lists!$O$5)&"") | P17: =IF(Lists!$O$5="","",INDEX(Stories!$J$4:$J$153,Lists!$O$5)&"") | R17: =IF(Lists!$O$5="","",INDEX(Stories!$A$4:$A$153,Lists!$O$5)) | S17: =IF(Lists!$O$5="","",INDEX(Stories!$F$4:$F$153,Lists!$O$5)&"")
B18: =IF(Lists!$O$6="","",5) | C18: =IF(Lists!$O$6="","",IF(AND(Lists!$P$6<>"",LEN(Lists!$P$6)<=255),HYPERLINK(Lists!$P$6,Lists!$Q$6),HYPERLINK("#'Stories'!B"&(Lists!$O$6+3),Lists!$Q$6))) | I18: =IF(Lists!$O$6="","",INDEX(Stories!$K$4:$K$153,Lists!$O$6)) | J18: =IF(Lists!$O$6="","",INDEX(Stories!$C$4:$C$153,Lists!$O$6)&"") | M18: =IF(Lists!$O$6="","",INDEX(Stories!$D$4:$D$153,Lists!$O$6)) | N18: =IF(Lists!$O$6="","",INDEX(Stories!$E$4:$E$153,Lists!$O$6)&"") | P18: =IF(Lists!$O$6="","",INDEX(Stories!$J$4:$J$153,Lists!$O$6)&"") | R18: =IF(Lists!$O$6="","",INDEX(Stories!$A$4:$A$153,Lists!$O$6)) | S18: =IF(Lists!$O$6="","",INDEX(Stories!$F$4:$F$153,Lists!$O$6)&"")
B19: =IF(Lists!$O$7="","",6) | C19: =IF(Lists!$O$7="","",IF(AND(Lists!$P$7<>"",LEN(Lists!$P$7)<=255),HYPERLINK(Lists!$P$7,Lists!$Q$7),HYPERLINK("#'Stories'!B"&(Lists!$O$7+3),Lists!$Q$7))) | I19: =IF(Lists!$O$7="","",INDEX(Stories!$K$4:$K$153,Lists!$O$7)) | J19: =IF(Lists!$O$7="","",INDEX(Stories!$C$4:$C$153,Lists!$O$7)&"") | M19: =IF(Lists!$O$7="","",INDEX(Stories!$D$4:$D$153,Lists!$O$7)) | N19: =IF(Lists!$O$7="","",INDEX(Stories!$E$4:$E$153,Lists!$O$7)&"") | P19: =IF(Lists!$O$7="","",INDEX(Stories!$J$4:$J$153,Lists!$O$7)&"") | R19: =IF(Lists!$O$7="","",INDEX(Stories!$A$4:$A$153,Lists!$O$7)) | S19: =IF(Lists!$O$7="","",INDEX(Stories!$F$4:$F$153,Lists!$O$7)&"")
B20: =IF(Lists!$O$8="","",7) | C20: =IF(Lists!$O$8="","",IF(AND(Lists!$P$8<>"",LEN(Lists!$P$8)<=255),HYPERLINK(Lists!$P$8,Lists!$Q$8),HYPERLINK("#'Stories'!B"&(Lists!$O$8+3),Lists!$Q$8))) | I20: =IF(Lists!$O$8="","",INDEX(Stories!$K$4:$K$153,Lists!$O$8)) | J20: =IF(Lists!$O$8="","",INDEX(Stories!$C$4:$C$153,Lists!$O$8)&"") | M20: =IF(Lists!$O$8="","",INDEX(Stories!$D$4:$D$153,Lists!$O$8)) | N20: =IF(Lists!$O$8="","",INDEX(Stories!$E$4:$E$153,Lists!$O$8)&"") | P20: =IF(Lists!$O$8="","",INDEX(Stories!$J$4:$J$153,Lists!$O$8)&"") | R20: =IF(Lists!$O$8="","",INDEX(Stories!$A$4:$A$153,Lists!$O$8)) | S20: =IF(Lists!$O$8="","",INDEX(Stories!$F$4:$F$153,Lists!$O$8)&"")
B21: =IF(Lists!$O$9="","",8) | C21: =IF(Lists!$O$9="","",IF(AND(Lists!$P$9<>"",LEN(Lists!$P$9)<=255),HYPERLINK(Lists!$P$9,Lists!$Q$9),HYPERLINK("#'Stories'!B"&(Lists!$O$9+3),Lists!$Q$9))) | I21: =IF(Lists!$O$9="","",INDEX(Stories!$K$4:$K$153,Lists!$O$9)) | J21: =IF(Lists!$O$9="","",INDEX(Stories!$C$4:$C$153,Lists!$O$9)&"") | M21: =IF(Lists!$O$9="","",INDEX(Stories!$D$4:$D$153,Lists!$O$9)) | N21: =IF(Lists!$O$9="","",INDEX(Stories!$E$4:$E$153,Lists!$O$9)&"") | P21: =IF(Lists!$O$9="","",INDEX(Stories!$J$4:$J$153,Lists!$O$9)&"") | R21: =IF(Lists!$O$9="","",INDEX(Stories!$A$4:$A$153,Lists!$O$9)) | S21: =IF(Lists!$O$9="","",INDEX(Stories!$F$4:$F$153,Lists!$O$9)&"")
B22: =IF(Lists!$O$10="","",9) | C22: =IF(Lists!$O$10="","",IF(AND(Lists!$P$10<>"",LEN(Lists!$P$10)<=255),HYPERLINK(Lists!$P$10,Lists!$Q$10),HYPERLINK("#'Stories'!B"&(Lists!$O$10+3),Lists!$Q$10))) | I22: =IF(Lists!$O$10="","",INDEX(Stories!$K$4:$K$153,Lists!$O$10)) | J22: =IF(Lists!$O$10="","",INDEX(Stories!$C$4:$C$153,Lists!$O$10)&"") | M22: =IF(Lists!$O$10="","",INDEX(Stories!$D$4:$D$153,Lists!$O$10)) | N22: =IF(Lists!$O$10="","",INDEX(Stories!$E$4:$E$153,Lists!$O$10)&"") | P22: =IF(Lists!$O$10="","",INDEX(Stories!$J$4:$J$153,Lists!$O$10)&"") | R22: =IF(Lists!$O$10="","",INDEX(Stories!$A$4:$A$153,Lists!$O$10)) | S22: =IF(Lists!$O$10="","",INDEX(Stories!$F$4:$F$153,Lists!$O$10)&"")
B23: =IF(Lists!$O$11="","",10) | C23: =IF(Lists!$O$11="","",IF(AND(Lists!$P$11<>"",LEN(Lists!$P$11)<=255),HYPERLINK(Lists!$P$11,Lists!$Q$11),HYPERLINK("#'Stories'!B"&(Lists!$O$11+3),Lists!$Q$11))) | I23: =IF(Lists!$O$11="","",INDEX(Stories!$K$4:$K$153,Lists!$O$11)) | J23: =IF(Lists!$O$11="","",INDEX(Stories!$C$4:$C$153,Lists!$O$11)&"") | M23: =IF(Lists!$O$11="","",INDEX(Stories!$D$4:$D$153,Lists!$O$11)) | N23: =IF(Lists!$O$11="","",INDEX(Stories!$E$4:$E$153,Lists!$O$11)&"") | P23: =IF(Lists!$O$11="","",INDEX(Stories!$J$4:$J$153,Lists!$O$11)&"") | R23: =IF(Lists!$O$11="","",INDEX(Stories!$A$4:$A$153,Lists!$O$11)) | S23: =IF(Lists!$O$11="","",INDEX(Stories!$F$4:$F$153,Lists!$O$11)&"")
C24: Ranked by relevance, then keyword score, then newest digest. Find a story in the Stories sheet by its Story No.
B26: Stories by theme
B27: Theme | F27: Stories | G27: Rated 5 | H27: Rated 4 | I27: Feature leads | J27: Share
B28: Sustainability & the Energy Transition | F28: =SUMPRODUCT(Stories!$W$4:$W$153,--(Stories!$C$4:$C$153=$B28)) | G28: =SUMPRODUCT(Stories!$W$4:$W$153,--(Stories!$C$4:$C$153=$B28),--(Stories!$D$4:$D$153=5)) | H28: =SUMPRODUCT(Stories!$W$4:$W$153,--(Stories!$C$4:$C$153=$B28),--(Stories!$D$4:$D$153=4)) | I28: =SUMPRODUCT(Stories!$W$4:$W$153,--(Stories!$C$4:$C$153=$B28),--(Stories!$E$4:$E$153="Feature lead")) | J28: =IF(Lists!$H$6=0,0,F28/Lists!$H$6)
B29: Digital Geotechnics | F29: =SUMPRODUCT(Stories!$W$4:$W$153,--(Stories!$C$4:$C$153=$B29)) | G29: =SUMPRODUCT(Stories!$W$4:$W$153,--(Stories!$C$4:$C$153=$B29),--(Stories!$D$4:$D$153=5)) | H29: =SUMPRODUCT(Stories!$W$4:$W$153,--(Stories!$C$4:$C$153=$B29),--(Stories!$D$4:$D$153=4)) | I29: =SUMPRODUCT(Stories!$W$4:$W$153,--(Stories!$C$4:$C$153=$B29),--(Stories!$E$4:$E$153="Feature lead")) | J29: =IF(Lists!$H$6=0,0,F29/Lists!$H$6)
B30: Hazards & Resilience | F30: =SUMPRODUCT(Stories!$W$4:$W$153,--(Stories!$C$4:$C$153=$B30)) | G30: =SUMPRODUCT(Stories!$W$4:$W$153,--(Stories!$C$4:$C$153=$B30),--(Stories!$D$4:$D$153=5)) | H30: =SUMPRODUCT(Stories!$W$4:$W$153,--(Stories!$C$4:$C$153=$B30),--(Stories!$D$4:$D$153=4)) | I30: =SUMPRODUCT(Stories!$W$4:$W$153,--(Stories!$C$4:$C$153=$B30),--(Stories!$E$4:$E$153="Feature lead")) | J30: =IF(Lists!$H$6=0,0,F30/Lists!$H$6)
B31: Ground Improvement & Innovation | F31: =SUMPRODUCT(Stories!$W$4:$W$153,--(Stories!$C$4:$C$153=$B31)) | G31: =SUMPRODUCT(Stories!$W$4:$W$153,--(Stories!$C$4:$C$153=$B31),--(Stories!$D$4:$D$153=5)) | H31: =SUMPRODUCT(Stories!$W$4:$W$153,--(Stories!$C$4:$C$153=$B31),--(Stories!$D$4:$D$153=4)) | I31: =SUMPRODUCT(Stories!$W$4:$W$153,--(Stories!$C$4:$C$153=$B31),--(Stories!$E$4:$E$153="Feature lead")) | J31: =IF(Lists!$H$6=0,0,F31/Lists!$H$6)
B32: Infrastructure & the Underground City | F32: =SUMPRODUCT(Stories!$W$4:$W$153,--(Stories!$C$4:$C$153=$B32)) | G32: =SUMPRODUCT(Stories!$W$4:$W$153,--(Stories!$C$4:$C$153=$B32),--(Stories!$D$4:$D$153=5)) | H32: =SUMPRODUCT(Stories!$W$4:$W$153,--(Stories!$C$4:$C$153=$B32),--(Stories!$D$4:$D$153=4)) | I32: =SUMPRODUCT(Stories!$W$4:$W$153,--(Stories!$C$4:$C$153=$B32),--(Stories!$E$4:$E$153="Feature lead")) | J32: =IF(Lists!$H$6=0,0,F32/Lists!$H$6)
B33: Offshore, Coasts & Water | F33: =SUMPRODUCT(Stories!$W$4:$W$153,--(Stories!$C$4:$C$153=$B33)) | G33: =SUMPRODUCT(Stories!$W$4:$W$153,--(Stories!$C$4:$C$153=$B33),--(Stories!$D$4:$D$153=5)) | H33: =SUMPRODUCT(Stories!$W$4:$W$153,--(Stories!$C$4:$C$153=$B33),--(Stories!$D$4:$D$153=4)) | I33: =SUMPRODUCT(Stories!$W$4:$W$153,--(Stories!$C$4:$C$153=$B33),--(Stories!$E$4:$E$153="Feature lead")) | J33: =IF(Lists!$H$6=0,0,F33/Lists!$H$6)
B34: Characterisation & Modelling | F34: =SUMPRODUCT(Stories!$W$4:$W$153,--(Stories!$C$4:$C$153=$B34)) | G34: =SUMPRODUCT(Stories!$W$4:$W$153,--(Stories!$C$4:$C$153=$B34),--(Stories!$D$4:$D$153=5)) | H34: =SUMPRODUCT(Stories!$W$4:$W$153,--(Stories!$C$4:$C$153=$B34),--(Stories!$D$4:$D$153=4)) | I34: =SUMPRODUCT(Stories!$W$4:$W$153,--(Stories!$C$4:$C$153=$B34),--(Stories!$E$4:$E$153="Feature lead")) | J34: =IF(Lists!$H$6=0,0,F34/Lists!$H$6)
B35: Geotechnics & Society | F35: =SUMPRODUCT(Stories!$W$4:$W$153,--(Stories!$C$4:$C$153=$B35)) | G35: =SUMPRODUCT(Stories!$W$4:$W$153,--(Stories!$C$4:$C$153=$B35),--(Stories!$D$4:$D$153=5)) | H35: =SUMPRODUCT(Stories!$W$4:$W$153,--(Stories!$C$4:$C$153=$B35),--(Stories!$D$4:$D$153=4)) | I35: =SUMPRODUCT(Stories!$W$4:$W$153,--(Stories!$C$4:$C$153=$B35),--(Stories!$E$4:$E$153="Feature lead")) | J35: =IF(Lists!$H$6=0,0,F35/Lists!$H$6)
B36: General | F36: =SUMPRODUCT(Stories!$W$4:$W$153,--(Stories!$C$4:$C$153=$B36)) | G36: =SUMPRODUCT(Stories!$W$4:$W$153,--(Stories!$C$4:$C$153=$B36),--(Stories!$D$4:$D$153=5)) | H36: =SUMPRODUCT(Stories!$W$4:$W$153,--(Stories!$C$4:$C$153=$B36),--(Stories!$D$4:$D$153=4)) | I36: =SUMPRODUCT(Stories!$W$4:$W$153,--(Stories!$C$4:$C$153=$B36),--(Stories!$E$4:$E$153="Feature lead")) | J36: =IF(Lists!$H$6=0,0,F36/Lists!$H$6)
B38: Suggested editorial use | H38: Geotechnical relevance | N38: Planning status
B39: Use | E39: Stories | F39: Share | H39: Relevance | K39: Stories | L39: Share | N39: Status | Q39: Stories | R39: Share
B40: Feature lead | E40: =SUMPRODUCT(Stories!$W$4:$W$153,--(Stories!$E$4:$E$153=$B40)) | F40: =IF(Lists!$H$6=0,0,E40/Lists!$H$6) | H40: 5 / 5 | K40: =COUNTIFS(Stories!$W$4:$W$153,1,Stories!$D$4:$D$153,5) | L40: =IF(Lists!$H$6=0,0,K40/Lists!$H$6) | N40: To review | Q40: =COUNTIFS(Stories!$W$4:$W$153,1,Stories!$F$4:$F$153,"To review") | R40: =IF(Lists!$H$6=0,0,Q40/Lists!$H$6)
B41: News brief | E41: =SUMPRODUCT(Stories!$W$4:$W$153,--(Stories!$E$4:$E$153=$B41)) | F41: =IF(Lists!$H$6=0,0,E41/Lists!$H$6) | H41: 4 / 5 | K41: =COUNTIFS(Stories!$W$4:$W$153,1,Stories!$D$4:$D$153,4) | L41: =IF(Lists!$H$6=0,0,K41/Lists!$H$6) | N41: Shortlisted | Q41: =COUNTIFS(Stories!$W$4:$W$153,1,Stories!$F$4:$F$153,"Shortlisted") | R41: =IF(Lists!$H$6=0,0,Q41/Lists!$H$6)
B42: Academia-to-Industry topic | E42: =SUMPRODUCT(Stories!$W$4:$W$153,--(Stories!$E$4:$E$153=$B42)) | F42: =IF(Lists!$H$6=0,0,E42/Lists!$H$6) | H42: 3 / 5 | K42: =COUNTIFS(Stories!$W$4:$W$153,1,Stories!$D$4:$D$153,3) | L42: =IF(Lists!$H$6=0,0,K42/Lists!$H$6) | N42: Commissioned | Q42: =COUNTIFS(Stories!$W$4:$W$153,1,Stories!$F$4:$F$153,"Commissioned") | R42: =IF(Lists!$H$6=0,0,Q42/Lists!$H$6)
B43: Regional insight | E43: =SUMPRODUCT(Stories!$W$4:$W$153,--(Stories!$E$4:$E$153=$B43)) | F43: =IF(Lists!$H$6=0,0,E43/Lists!$H$6) | N43: Published | Q43: =COUNTIFS(Stories!$W$4:$W$153,1,Stories!$F$4:$F$153,"Published") | R43: =IF(Lists!$H$6=0,0,Q43/Lists!$H$6)
B44: Watch only | E44: =SUMPRODUCT(Stories!$W$4:$W$153,--(Stories!$E$4:$E$153=$B44)) | F44: =IF(Lists!$H$6=0,0,E44/Lists!$H$6) | N44: Not used | Q44: =COUNTIFS(Stories!$W$4:$W$153,1,Stories!$F$4:$F$153,"Not used") | R44: =IF(Lists!$H$6=0,0,Q44/Lists!$H$6)
B59: Theme × suggested use (heat map for this selection)
...

Sheet Stories
A1: Stories · 150 in this workbook | C1: ← Dashboard | D1: ↑ Start here | E1: By theme →
C2: Gold columns are yours: choose a Status from its dropdown, and fill in Assigned to and Editor notes. Use ▼ in the header to filter or sort. ✓ in ‘In Dashboard selection’ (far right) marks the stories the Dashboard is showing.
A3: No. | B3: Headline (English or Claude's translation) | C3: Theme | D3: Relevance | E3: Suggested use | F3: Status | G3: Assigned to | H3: Editor notes | I3: Magazine angle | J3: Source | K3: Digest date | L3: Original headline | M3: Primary source to check | N3: Country | O3: Place | P3: Developing story | Q3: Google News edition | R3: Published | S3: Issue window | T3: Keywords | U3: Keyword score | V3: Article URL | W3: In Dashboard selection | X3: Top-10 key (helper)
A4: 1 | B4: Kumamoto earthquake: 96% of liquefaction sites reoccurred | C4: Hazards & Resilience | D4: 5 | E4: Feature lead | F4: To review | I4: Why do the same sites re-liquefy in repeated earthquakes, and which ground improvement or site-specific measures actually stop recurrence? | J4: Yahoo!ニュース | K4: 46321 | L4: 熊本地震 液状化地点の96%で再発 | M4: Kumamoto Prefectural Government and the research team behind the liquefaction survey | N4: Japan | O4: Kumamoto Prefecture | Q4: Japan | R4: 46321 | S4: 2026-Q4 | T4: liquefaction, earthquake | U4: 7 | V4: https://news.google.com/rss/articles/CBMiUEFVX3lxTE9sUlNwdEcwMURBRkNDb3dEd0NfVFIzaG9RTUMtYkQ0dnNpT3ByQjFVWFJPYkhjWDNqOFlXNkVrOFk3VzB6NHB1MGtjU1Bfa0d6?oc=5 | W4: =IF($B4="",0,IF(AND(OR(OR(Dashboard!$B$5="All themes",Dashboard!$B$5=""),$C4=Dashboard!$B$5),OR(OR(Dashboard!$G$5="All uses",Dashboard!$G$5=""),$E4=Dashboard!$G$5),N($D4)>=Lists!$H$2,OR(OR(Dashboard!$N$5="All windows",Dashboard!$N$5=""),$S4=Dashboard!$N$5)),1,0)) | X4: =IF($W4=1,N($D4)*1E14+MIN(MAX(N($U4),0),9999)*1E10+MIN(N($K4),99999)*1E5+99999-MIN(ROW(),99999),"")
A5: 2 | B5: 96% of sites with upper seismic intensity 6 in the Kumamoto earthquake re-liquefied; experts urge advance countermeasures. | C5: Hazards & Resilience | D5: 5 | E5: Watch only | F5: To review | I5: Why do the same sites re-liquefy in repeated earthquakes, and which ground improvement or site-specific measures actually stop recurrence? | J5: 読売新聞 | K5: 46321 | L5: 熊本地震「震度６強」の９６％が再液状化…繰り返される被害、専門家は事前対策訴え | M5: Kumamoto Prefectural Government and the research team behind the liquefaction survey | N5: Japan | O5: Kumamoto Prefecture | Q5: Japan | R5: 46320 | S5: 2026-Q4 | T5: liquefaction, earthquake | U5: 7 | V5: https://news.google.com/rss/articles/CBMiZkFVX3lxTFA3VmNVcVpnS3U1V0ZuanVlb3VQdnhpaDN3NGlETGFPa3h5bURmWGJUUGJsdjh6SENpWGFUUHNGa3pMbUJNd0FndDBkakstVzV2b0U5bjVMOFRFVDFrTS1ob3RwTTZPZw?oc=5 | W5: =IF($B5="",0,IF(AND(OR(OR(Dashboard!$B$5="All themes",Dashboard!$B$5=""),$C5=Dashboard!$B$5),OR(OR(Dashboard!$G$5="All uses",Dashboard!$G$5=""),$E5=Dashboard!$G$5),N($D5)>=Lists!$H$2,OR(OR(Dashboard!$N$5="All windows",Dashboard!$N$5=""),$S5=Dashboard!$N$5)),1,0)) | X5: =IF($W5=1,N($D5)*1E14+MIN(MAX(N($U5),0),9999)*1E10+MIN(N($K5),99999)*1E5+99999-MIN(ROW(),99999),"")
A6: 3 | B6: Ancient Earthquakes Triggered Massive 10,000-Year-Old Landslides In Kashmir Himalaya, New Study Reveals | C6: Hazards & Resilience | D6: 5 | E6: Feature lead | F6: To review | I6: Can dating of ancient landslide deposits be used to infer earthquake recurrence and slope hazard in tectonically active Himalayan terrain? | J6: Kashmir Life | K6: 46321 | M6: the study's lead research institution (check the journal paper) | N6: India | O6: Kashmir Himalaya | Q6: United Kingdom | R6: 46321 | S6: 2026-Q4 | T6: landslide, earthquake | U6: 6 | V6: https://news.google.com/rss/articles/CBMizgFBVV95cUxPeUtDQ05KR3BiV2d5RkNjVUJSb29EZlZaRks5VlJvb1g3STk4dEliaDZ1Smt3Yk53bnFJdndubXJYN0xXZkNGV0ZpT09ZZVdmTWpWUHNpUFo4Z2hiTFFVQkVjaWJ5aEZOYnUzakhPNHVWVmx4U0V0c1ZBU1owYUhRLVNUNy12d1N5U3ZHOVB3bE5kOW5yRndjQXc2am5YUGdMbmJQQ19EVVpGTEJXLUpYTFY0QUpkS0FPZ0wxdDdLejZ1RVBGZkZaOEFQR0lEZw?oc=5 | W6: =IF($B6="",0,IF(AND(OR(OR(Dashboard!$B$5="All themes",Dashboard!$B$5=""),$C6=Dashboard!$B$5),OR(OR(Dashboard!$G$5="All uses",Dashboard!$G$5=""),$E6=Dashboard!$G$5),N($D6)>=Lists!$H$2,OR(OR(Dashboard!$N$5="All windows",Dashboard!$N$5=""),$S6=Dashboard!$N$5)),1,0)) | X6: =IF($W6=1,N($D6)*1E14+MIN(MAX(N($U6),0),9999)*1E10+MIN(N($K6),99999)*1E5+99999-MIN(ROW(),99999),"")
A7: 4 | B7: Niscemi, nine months after the landslide: the town hanging over the void and thirty years of broken promises. | C7: Hazards & Resilience | D7: 5 | E7: Feature lead | F7: To review | I7: Why does a large landslide keep a hilltop town in limbo months later, and what geotechnical monitoring and stabilisation strategy could justify either remaining or relocating residents? | J7: la Repubblica | K7: 46321 | L7: Niscemi, nove mesi dopo la frana: la città sospesa sul vuoto e trent'anni di promesse tradite | M7: Italian Civil Protection Department and Comune di Niscemi | N7: Italy | O7: Niscemi, Sicily | P7: Niscemi landslide, Sicily (Jan 2026) · Update · 2 reports | Q7: Italy | R7: 46321 | S7: 2026-Q4 | T7: landslide | U7: 4 | V7: https://news.google.com/rss/articles/CBMiqwFBVV95cUxQUVljZ2Z4NlVrQkw3RXVnMUxoZ1hCVjRvWjJ4TDlQSVRaaHF3RFRILUxNck1KQXB3RS1wTTlnZEhyMkxlMjBqR25udVNxVXZFLXRhX0IyX2VuUGJDTEl1a1RPUS1tcDRmd3hkWmpEQnQ4UF91dF9MY25OcEZ1czBzaXNlZFVuTjZxVVVCN0JKNVBtSmZtRUlvNV94Q1dzRWxuYlU5UXdGUTdaMzDSAasBQVVfeXFMUFFZY2dmeDZVa0JMN0V1ZzFMaGdYQlY0b1oyeEw5UElUWmhxd0RUSC1MTXJNSkFwd0UtcE05Z2RIcjJMZTIwakdubnVTcVV2RS10YV9CMl9lblBiQ0xJdWtUT1EtbXA0Znd4ZFpqREJ0OFBfdXRfTGNuTnBGdXMwc2lzZWRVbk42cVVVQjdCSjVQbUpmbUVJbzVfeENXc0VsbmJVOVF3RlE3WjMw?oc=5 | W7: =IF($B7="",0,IF(AND(OR(OR(Dashboard!$B$5="All themes",Dashboard!$B$5=""),$C7=Dashboard!$B$5),OR(OR(Dashboard!$G$5="All uses",Dashboard!$G$5=""),$E7=Dashboard!$G$5),N($D7)>=Lists!$H$2,OR(OR(Dashboard!$N$5="All windows",Dashboard!$N$5=""),$S7=Dashboard!$N$5)),1,0)) | X7: =IF($W7=1,N($D7)*1E14+MIN(MAX(N($U7),0),9999)*1E10+MIN(N($K7),99999)*1E5+99999-MIN(ROW(),99999),"")
A8: 5 | B8: Liu Yushui garden earth collapse kills; SAM says it warned repeatedly about hillside development risks | C8: Hazards & Resilience | D8: 5 | E8: Feature lead | F8: To review | I8: How do hillside development practices and repeated unheeded warnings contribute to fatal slope failures, and what geotechnical due diligence should apply to hillside housing? | J8: China Press | K8: 46321 | L8: 刘玉水花园土崩夺命 SAM：已多次警告 山坡发展风险 | M8: Penang state government and the police | N8: Malaysia | P8: Paya Terubong landslide, Penang, Malaysia (Oct 2026) · Investigation & inquiry · 7 reports | Q8: China | R8: 46320 | S8: 2026-Q4 | T8: slope | U8: 2 | V8: https://news.google.com/rss/articles/CBMi2wJBVV95cUxPaUpqb21fRVV2bFlHYU5ud1p3NFVmYVpIMWN4U2Z5S1lOS2lVWGpsb0p4ZnIwZUIxOHQ4OVNXTlhjTWg2Nk9CRTI4cEY1VEJRREV6SmxiQnliUF9pYmh4ekpfQUkwRGxsYW9TOFE1VzdxTDc5bmk2Z2RGbTduX3lIVDVrbFN0eXlualBsSFZ6TzJranBnWi1TSHlKT1FhTDQ5bFpwODI0RVhTVTlOYW9iNjhGc1puZGJkQ1kwUTdZb2IxY1FHTV9DRWFvYnJPd1lWb3ZyOTNxMVNRTGtwd0w0a0RXaFRRMG1WZ1RKUDk0OUJQMHJTN3VjNm5DanhLR3g3eTRmQm8tU1F0bm5EVHJCUkFvR05hejY3NWFPNmhmUkxSZlJFSjFOTVdLRmEyVVY1akMxdWNNSjUzSWhyMmVaTDE5cWhoS2NRWEdrTWVmdE80SUZ6Uldlb0VTZw?oc=5 | W8: =IF($B8="",0,IF(AND(OR(OR(Dashboard!$B$5="All themes",Dashboard!$B$5=""),$C8=Dashboard!$B$5),OR(OR(Dashboard!$G$5="All uses",Dashboard!$G$5=""),$E8=Dashboard!$G$5),N($D8)>=Lists!$H$2,OR(OR(Dashboard!$N$5="All windows",Dashboard!$N$5=""),$S8=Dashboard!$N$5)),1,0)) | X8: =IF($W8=1,N($D8)*1E14+MIN(MAX(N($U8),0),9999)*1E10+MIN(N($K8),99999)*1E5+99999-MIN(ROW(),99999),"")
A9: 6 | B9: Ground crumbles and gas escapes: thousands of dangerous sites identified in Yamal | C9: Sustainability & the Energy Transition | D9: 5 | E9: Feature lead | F9: To review | I9: How is permafrost thaw and gas migration causing ground collapse and craters across Yamal, and what monitoring and foundation strategies can manage thousands of hazardous sites? | J9: Life.ru | K9: 46321 | L9: Грунт рушится, а газ рвётся наружу: На Ямале выявили тысячи опасных участков | M9: Yamal regional authorities and the gas operators | N9: Russia | O9: Yamal | Q9: Russia | R9: 46320 | S9: 2026-Q4 | T9: soil | U9: 1 | V9: https://news.google.com/rss/articles/CBMilgFBVV95cUxNdFl6QWFvMFBRQ3hMOFc2S0hRdkIzNWViQXFZaFB1b2h5eEx5czUwbnhOeFNKX3MybWRfLVhhdlJjb0s0eFUtMDloNFJoUTEtb0dRRElGdllDbFVOejZFS0o4NzUwN2lhNlkyMzdlZzBCR1NpaXhKN1ZSZjZHRG1RV1JFQVpJRFNxQW1xcTBZWUMxWnVxRnc?oc=5 | W9: =IF($B9="",0,IF(AND(OR(OR(Dashboard!$B$5="All themes",Dashboard!$B$5=""),$C9=Dashboard!$B$5),OR(OR(Dashboard!$G$5="All uses",Dashboard!$G$5=""),$E9=Dashboard!$G$5),N($D9)>=Lists!$H$2,OR(OR(Dashboard!$N$5="All windows",Dashboard!$N$5=""),$S9=Dashboard!$N$5)),1,0)) | X9: =IF($W9=1,N($D9)*1E14+MIN(MAX(N($U9),0),9999)*1E10+MIN(N($K9),99999)*1E5+99999-MIN(ROW(),99999),"")
A10: 7 | B10: Silkyara tunnel may open before the upcoming Char Dham yatra, company claims; Yamunotri distance to shrink by 26 km | C10: Infrastructure & the Underground City | D10: 5 | E10: Feature lead | F10: To review | I10: What ground stabilisation and rock mass conditions must be verified before a collapsed Himalayan tunnel can safely reopen, and how credible is the proposed schedule? | J10: Dainik Bhaskar | K10: 46321 | L10: सिलक्यारा टनल आगामी चारधाम यात्रा तक खुल सकती है: कंपनी का दावा; यमुनोत्री धाम की 26 किमी दूरी घटेगी, समय औ... | M10: NHIDCL (the project owner) and the contractor | N10: India | O10: Silkyara tunnel, Uttarkashi | Q10: India | R10: 46320 | S10: 2026-Q4 | U10: 0 | V10: https://news.google.com/rss/articles/CBMi1gFBVV95cUxNYUVkaGtnY09kNFJzUnNQUmFla3RVLUJyMzRiTy1aWGtEWmVrMWNCeFF0YWJBLTd1dHN2VVd2UlFNZGNTNWlFNUZOdU1RbWl0NWloV1MyUWZoOUkxOUhubWZqbl9IQndyY2VLTUFQZjV4RW55bmdWUHE0YmFXNnZDRHlLS0hiQTllQVJxQ1d2Si1VYjhtcWxmR05hZGJ0MzZONmlaX1VpZm41TWs2QXROM2p6a1U4cnViakV1TWRTNklwakJRdkpVZjBlNDJEVFVwLXRzMFVR0gHWAUFVX3lxTE1hRWRoa2djT2Q0UnNSc1BSYWVrdFUtQnIzNGJPLVpYa0RaZWsxY0J4UXRhYkEtN3V0c3ZVV3ZSUU1kY1M1aUU1Rk51TVFtaXQ1aWhXUzJRZmg5STE5SG5tZmpuX0hCd3JjZUtNQVBmNXhFbnluZ1ZQcTRiYVc2dkNEeUtLSGJBOWVBUnFDV3ZKLVViOG1xbGZHTmFkYnQzNk42aVpfVWlmbjVNazZBdE4zanprVThydWJqRXVNZFM2SXBqQlF2SlVmMGU0MkRUVXAtdHMwVVE?oc=5 | W10: =IF($B10="",0,IF(AND(OR(OR(Dashboard!$B$5="All themes",Dashboard!$B$5=""),$C10=Dashboard!$B$5),OR(OR(Dashboard!$G$5="All uses",Dashboard!$G$5=""),$E10=Dashboard!$G$5),N($D10)>=Lists!$H$2,OR(OR(Dashboard!$N$5="All windows",Dashboard!$N$5=""),$S10=Dashboard!$N$5)),1,0)) | X10: =IF($W10=1,N($D10)*1E14+MIN(MAX(N($U10),0),9999)*1E10+MIN(N($K10),99999)*1E5+99999-MIN(ROW(),99999),"")
A11: 8 | B11: Rock blocks over 500 tonnes threaten Turkey–Georgia road; experts demand inspection of 50 km | C11: Hazards & Resilience | D11: 5 | E11: Feature lead | F11: To review | I11: How can rockfall hazard along a mountain highway be assessed for very large blocks, and what slope-scaling and stabilisation approach suits a 50 km stretch? | J11: تركيا عاجل | K11: 46321 | L11: كتل صخرية تتجاوز 500 طن تهدد طريق تركيا-جورجيا.. خبراء يطالبون بفحص 50 كيلومترًا | M11: the General Directorate of Highways (KGM) | N11: Türkiye | O11: Turkey–Georgia road | Q11: Egypt | R11: 46320 | S11: 2026-Q4 | U11: 0 | V11: https://news.google.com/rss/articles/CBMi3wJBVV95cUxPSDh4cHZPcTZteEUtQTEtU2lZdGtHRUZiWDQwV192QUxleXF4TVZCTEY4XzR5Vmc3dmd1TEJxUFAxdy0yZjNBUzJ1cEhtTW9HRHhKUlRJdnp6SF9STE1EVnNRMFJYVVVWaDU2c0hCY00yQU9leVA0ZHpXaGMyMER1LVNuZHZybktTU2E0R0dfTkdMNnJMYjhsenNqT3diVGY5MFowZGNHNFIxVEg4S01LclRER0l0QW5BSUFDb1E4WndWcGtwYTZOX3BIZEZIaXNic2cyTjdGV09QNlJfVnJOcTl1WG5kTXEtZm40MXhJLVpQdktQanlCcThBeXl2VHRDSGxQc1FrZ0hYTkpTRUpmbTNneVdxS0tvaGtxNF9PVWRBaHBPUDZBSEVkTk5qOHdtMzV1a0Zncy1HQ19NQTlDSnRLQ2dtU184WC1obWEyQUFaenoxWVFCRnpFazFCTkk?oc=5 | W11: =IF($B11="",0,IF(AND(OR(OR(Dashboard!$B$5="All themes",Dashboard!$B$5=""),$C11=Dashboard!$B$5),OR(OR(Dashboard!$G$5="All uses",Dashboard!$G$5=""),$E11=Dashboard!$G$5),N($D11)>=Lists!$H$2,OR(OR(Dashboard!$N$5="All windows",Dashboard!$N$5=""),$S11=Dashboard!$N$5)),1,0)) | X11: =IF($W11=1,N($D11)*1E14+MIN(MAX(N($U11),0),9999)*1E10+MIN(N($K11),99999)*1E5+99999-MIN(ROW(),99999),"")
A12: 9 | B12: Longwei earth collapse death: autopsy report released, cause is traumatic asphyxia | C12: Hazards & Resilience | D12: 5 | E12: Feature lead | F12: To review | I12: What does the post-mortem finding of a traumatic death reveal about the safety of hillside collapse rescue and the failure of earlier slope warnings? | J12: China Press | K12: 46321 | L12: 垄尾土崩酿一死｜死者解剖报告出炉 死因是创伤性窒息 | M12: Penang state government and the police | N12: Malaysia | Q12: China | R12: 46321 | S12: 2026-Q4 | U12: 0 | V12: https://news.google.com/rss/articles/CBMi2wJBVV95cUxNSldHQkhacnFXOW9uNFFPVC1kbkdZbW1KcVhfbjZGdGdIZFhBbmd5SjVCeGRtOW5vdllWQmFwZGo2bTdNOThuVmR0dkNDSjNMVHZQYmVSNldnNWhjRlRQR2VCTU0xSmZ4N0hJZ01XUGN0ZGI0dWtTLUpkS0poX3ZxRnVpY3FLLVpYQWZxRVktNFhjeVpwTXU5WWI0RGY3X3NhUG9UVHByNnFLRkpBbmxwYnE2Y3VUaWhZU0duOVlzNDk2YWNrVGsyOXlsREV3V3ZYM0o3ZVZXUk91Z2paQ1hlWE9haGZPemIwbVdvWjZLbTNjNkUzQlJNUmpDeTVQZTQxQzI3enk2UU5RX1lxNmlfa1NudG45WjE5SlotTXlaS3lhdW5MaEtwTDNESnVXajkwak04MUwwYUZiYW5FMHM3S2xSRTZKbGROazZQR0ZzS055aGh1Rl9Nc3pCdw?oc=5 | W12: =IF($B12="",0,IF(AND(OR(OR(Dashboard!$B$5="All themes",Dashboard!$B$5=""),$C12=Dashboard!$B$5),OR(OR(Dashboard!$G$5="All uses",Dashboard!$G$5=""),$E12=Dashboard!$G$5),N($D12)>=Lists!$H$2,OR(OR(Dashboard!$N$5="All windows",Dashboard!$N$5=""),$S12=Dashboard!$N$5)),1,0)) | X12: =IF($W12=1,N($D12)*1E14+MIN(MAX(N($U12),0),9999)*1E10+MIN(N($K12),99999)*1E5+99999-MIN(ROW(),99999),"")
A13: 10 | B13: Deslizamiento de talud afecta sótanos y locales de plaza comercial en Cuajimalpa | C13: Hazards & Resilience | D13: 4 | E13: Feature lead | F13: To review | I13: How should basements and retail excavations beside unstable natural slopes be designed and monitored so that slope movement does not reach occupied spaces? | J13: El Universal | K13: 46321 | M13: Mexico City Protección Civil and the borough's building authority | N13: Mexico | O13: Cuajimalpa, Mexico City | Q13: Spain | R13: 46321 | S13: 2026-Q4 | T13: landslide, retaining wall | U13: 8 | V13: https://news.google.com/rss/articles/CBMi3gFBVV95cUxQS0l6Zm44UzhLZWp1WEhEeDlhUDQ4YkJaaVMtcTVRdUZqV2N0YU9VWmFRb1Q1Q1dfdW12dFBKUTU4aHViU0NKOENyY0JKM3hQM2pxZng4QzlDMG45WVhydDJybkdZQ2tXY2VxUEdnTjRQSGFNZjdubGQ4UFlrYVhhVFhTMTg4SGszQkFMVDlha1lmdFZyVXBSYTJ3cENnN1RvQmtmeU9KZGlGcHgxeERaNC11MjVLeDV4eC13R090RnhHc0RQWFZBalRYNktRdVRpbHFWN19FR2NYeGx4dUHSAfIBQVVfeXFMTVEwQTl0MUFJZ1VtQXlLalgzS3BXTjFzVmJFeUFmU1BqZVZnY09VQWRCeTZTenNtLVBUT2JPbVFfZ2tGSzJyekF5Y0JWRUF6Sk4tdi1wN1FieTZUNEM2U2hJcGZBTFJNdkY1aDNkckc4Q0hFa2JaRFhDWVBMNnkzS3Nya2QzYVJRanVsVXN1MGUtTjJYTjNVNGVNWHR2bml0Q2tUSFhIMmR5c25XTmdlMGZ6TGVCc2ZHUW5XY1N2VXFUSUtzNUZGdlBpZFVGeDVjUl81QzVBTlhMOWd2eFJUNWdUOHhCZEhqR3pOYWtHRFBKVGc?oc=5 | W13: =IF($B13="",0,IF(AND(OR(OR(Dashboard!$B$5="All themes",Dashboard!$B$5=""),$C13=Dashboard!$B$5),OR(OR(Dashboard!$G$5="All uses",Dashboard!$G$5=""),$E13=Dashboard!$G$5),N($D13)>=Lists!$H$2,OR(OR(Dashboard!$N$5="All windows",Dashboard!$N$5=""),$S13=Dashboard!$N$5)),1,0)) | X13: =IF($W13=1,N($D13)*1E14+MIN(MAX(N($U13),0),9999)*1E10+MIN(N($K13),99999)*1E5+99999-MIN(ROW(),99999),"")
A14: 11 | B14: Fuerte deslave en Centro Santa Fe: colapsa talud de 30 metros y afecta locales | C14: Hazards & Resilience | D14: 4 | E14: Feature lead | F14: To review | I14: What failure mechanisms could bring down a 30 m cut slope in a dense urban business district, and what monitoring would have given early warning? | J14: PostaMx | K14: 46321 | M14: Mexico City Protección Civil and the developer's geotechnical consultant | N14: Mexico | O14: Centro Santa Fe, Mexico City | Q14: Spain | R14: 46321 | S14: 2026-Q4 | T14: landslide, retaining wall | U14: 8 | V14: https://news.google.com/rss/articles/CBMiyAFBVV95cUxQd1RPVUlZbTlJeGVMQi1xZjBBU0RZUVZnMkNFRlAtTzZVUTdXd3RWbTVGTDc1b2lnb2haM1YyM0pQQVF2MHBVMFZvdUpEN2hzQ2prQWhVT0hYNmxwZG9yQVNBWlF2SUlPbFpJN1VrdWNYRGRNdkJJejJReEFwZ080WUs0MTh5NHB1a2hJcWdOdWZpYlJscUg1RUhGX3dnRkJDazhMOUZrQ3BVQk1BNVJLZTNfUndUMXJEU05vd1NYSmkwYVpsdGowVdIByAFBVV95cUxQd1RPVUlZbTlJeGVMQi1xZjBBU0RZUVZnMkNFRlAtTzZVUTdXd3RWbTVGTDc1b2lnb2haM1YyM0pQQVF2MHBVMFZvdUpEN2hzQ2prQWhVT0hYNmxwZG9yQVNBWlF2SUlPbFpJN1VrdWNYRGRNdkJJejJReEFwZ080WUs0MTh5NHB1a2hJcWdOdWZpYlJscUg1RUhGX3dnRkJDazhMOUZrQ3BVQk1BNVJLZTNfUndUMXJEU05vd1NYSmkwYVpsdGowVQ?oc=5 | W14: =IF($B14="",0,IF(AND(OR(OR(Dashboard!$B$5="All themes",Dashboard!$B$5=""),$C14=Dashboard!$B$5),OR(OR(Dashboard!$G$5="All uses",Dashboard!$G$5=""),$E14=Dashboard!$G$5),N($D14)>=Lists!$H$2,OR(OR(Dashboard!$N$5="All windows",Dashboard!$N$5=""),$S14=Dashboard!$N$5)),1,0)) | X14: =IF($W14=1,N($D14)*1E14+MIN(MAX(N($U14),0),9999)*1E10+MIN(N($K14),99999)*1E5+99999-MIN(ROW(),99999),"")
A15: 12 | B15: Progress review of dyke and retaining wall packages to prevent landslides along the Tien River. | C15: Hazards & Resilience | D15: 4 | E15: Regional insight | F15: To review | I15: What design and construction sequencing issues arise when riverbank dykes and retaining walls are upgraded in stages along an active erosion-prone river? | J15: Vietnam.vn | K15: 46321 | L15: Meninjau kemajuan paket konstruksi dalam Proyek peningkatan tanggul dan dinding penahan untuk mencegah tanah longsor di sepanjang Sungai Tien. | M15: the provincial project management board for the Tien River dyke works | N15: Vietnam | O15: Tien River, Vietnam | Q15: Indonesia | R15: 46319 | S15: 2026-Q4 | T15: landslide, embankment | U15: 7 | V15: https://news.google.com/rss/articles/CBMiwgFBVV95cUxQMlJUSUZORHF4STQta0JTUE5jbGhUeEU2WjdzTTNtSTZZZEprbEpLX3lzS3ZEMTd4YWZhekVGaUJsVnJWUml5M3lMTjlNS0Z4UjgyMUUxZlpWMlB1R1FCWGt3MEczZDZ0Y2YwOVRhd01GUk9ORlJZZklUR1I0SnhwbmM3eGdod182eEdWZHM2dkQ2V1hLVTlwaTl1eVJ1dE4ycVlxd0pYWUlab2M4VnBVcG5EU0dRZVBZbmc3UHVkMHRrdw?oc=5 | W15: =IF($B15="",0,IF(AND(OR(OR(Dashboard!$B$5="All themes",Dashboard!$B$5=""),$C15=Dashboard!$B$5),OR(OR(Dashboard!$G$5="All uses",Dashboard!$G$5=""),$E15=Dashboard!$G$5),N($D15)>=Lists!$H$2,OR(OR(Dashboard!$N$5="All windows",Dashboard!$N$5=""),$S15=Dashboard!$N$5)),1,0)) | X15: =IF($W15=1,N($D15)*1E14+MIN(MAX(N($U15),0),9999)*1E10+MIN(N($K15),99999)*1E5+99999-MIN(ROW(),99999),"")
A16: 13 | B16: No signs of further slope movement at Paya Terubong landslide site, says MBPP | C16: Hazards & Resilience | D16: 4 | E16: Feature lead | F16: To review | I16: How should a landslide site be judged stable again after movement stops, and what monitoring period is needed before reoccupation? | J16: The Star | K16: 46321 | M16: Penang Municipal Council (MBPP) | N16: Malaysia | O16: Paya Terubong, Penang | P16: Paya Terubong landslide, Penang, Malaysia (Oct 2026) · Response & recovery · 7 reports | Q16: United Kingdom | R16: 46321 | S16: 2026-Q4 | T16: landslide, slope | U16: 6 | V16: https://news.google.com/rss/articles/CBMixAFBVV95cUxPYTBqYjFndGYzaFJ2VUxqdjg5SW5FNXZZczhJcmVKSDBHd3pQWThlXzRJc25mQVQzR0ZMdlg0eENhY1NkX3VTZjZJeGxhblFaRVhQWUd3UnEzTEFXVW5OZWM4QVVtR1k3UEk5bjVkUlNfcW1UTThGbTNBSEFCcEZ3S2Y1eG95dndkeHBlUF9TXzd3U1FSTlhreU1ZZGFtOWNUY1lLWnp5OE5wcUp0cGQ0TTdNWUJaOU1WNnU0cWJnMlBTUzVC?oc=5 | W16: =IF($B16="",0,IF(AND(OR(OR(Dashboard!$B$5="All themes",Dashboard!$B$5=""),$C16=Dashboard!$B$5),OR(OR(Dashboard!$G$5="All uses",Dashboard!$G$5=""),$E16=Dashboard!$G$5),N($D16)>=Lists!$H$2,OR(OR(Dashboard!$N$5="All windows",Dashboard!$N$5=""),$S16=Dashboard!$N$5)),1,0)) | X16: =IF($W16=1,N($D16)*1E14+MIN(MAX(N($U16),0),9999)*1E10+MIN(N($K16),99999)*1E5+99999-MIN(ROW(),99999),"")
A17: 14 | B17: State Govt urged to act on slope safety after landslide kills 73-year-old doctor | C17: Hazards & Resilience | D17: 4 | E17: Feature lead | F17: To review | I17: What would a credible state-wide slope inventory and maintenance regime look like for hill-slope housing in tropical, rain-driven terrain? | J17: The Vibes | K17: 46321 | M17: Penang state government and its slope safety authority | N17: Malaysia | O17: Penang | P17: Paya Terubong landslide, Penang, Malaysia (Oct 2026) · Legal & policy · 7 reports | Q17: Australia | R17: 46320 | S17: 2026-Q4 | T17: landslide, slope | U17: 6 | V17: https://news.google.com/rss/articles/CBMi0gFBVV95cUxQa2swTlk5dXpVVXAyeTNwM3ZqaExYMnhyTVdFOHA2bFhnaGpsYlAyYVlKdWxndHFvNEdrOEF1cFpSaE1wbm42MHd1UUVVNkdwclBzai1hTnNGV1JsdEttRms5SjdhUWtaZ2Z2REtHb09WUUZWZWFuZ2UyRTFzLWk3YjFFRnlXRGFuaGhGenBMekotdU1UM3NWcW5vYWtvRk9fUUw1cXl0alU1S09FZWhfUjRNV3dTZ3cwMlFOYzlYRnpQcXpseWkxQXo2NmJ0ejBJR3c?oc=5 | W17: =IF($B17="",0,IF(AND(OR(OR(Dashboard!$B$5="All themes",Dashboard!$B$5=""),$C17=Dashboard!$B$5),OR(OR(Dashboard!$G$5="All uses",Dashboard!$G$5=""),$E17=Dashboard!$G$5),N($D17)>=Lists!$H$2,OR(OR(Dashboard!$N$5="All windows",Dashboard!$N$5=""),$S17=Dashboard!$N$5)),1,0)) | X17: =IF($W17=1,N($D17)*1E14+MIN(MAX(N($U17),0),9999)*1E10+MIN(N($K17),99999)*1E5+99999-MIN(ROW(),99999),"")
A18: 15 | B18: Four Tourists Injured After Poolside Patio Collapses Into Sinkhole At Cozumel Resort | C18: Infrastructure & the Underground City | D18: 4 | E18: Feature lead | F18: To review | I18: How can shallow cavities in karst limestone be detected under resort paving and foundations before a patio collapses into a sinkhole? | J18: Cancun Sun | K18: 46321 | M18: Quintana Roo state civil protection and the resort's engineering consultant | N18: Mexico | O18: Cozumel, Quintana Roo | P18: Occidental Cozumel hotel sinkhole, Mexico (Oct 2026) · Event · 3 reports | Q18: United Kingdom | R18: 46320 | S18: 2026-Q4 | T18: sinkhole, collapse | U18: 5 | V18: https://news.google.com/rss/articles/CBMirwFBVV95cUxOVGZ5TmMxZlZmTTc2cjhZVXVvUlhHbnQ2VFhzbjFUck9PNkVDY01Lc2dYN3lLZVlXcUVkV0hhTmtOSkl4bnlVblNVZ0dlM1h0dVpia1RIcDV6YU5rRW5icDB2Z2RFRGZucFFRZ2J2UUpWSlB4dEFOTEwtaUtyQXhqQkNZeVNGZmtJV3JORy1VN3ZvV1JzSkdXbk9kNVkzb3FLRkVRdEtOdkYxVThCNmtZ?oc=5 | W18: =IF($B18="",0,IF(AND(OR(OR(Dashboard!$B$5="All themes",Dashboard!$B$5=""),$C18=Dashboard!$B$5),OR(OR(Dashboard!$G$5="All uses",Dashboard!$G$5=""),$E18=Dashboard!$G$5),N($D18)>=Lists!$H$2,OR(OR(Dashboard!$N$5="All windows",Dashboard!$N$5=""),$S18=Dashboard!$N$5)),1,0)) | X18: =IF($W18=1,N($D18)*1E14+MIN(MAX(N($U18),0),9999)*1E10+MIN(N($K18),99999)*1E5+99999-MIN(ROW(),99999),"")
A19: 16 | B19: В Пенанге оползень обрушился на дом, погиб 73-летний мужчина — Channel NewsAsia | C19: Hazards & Resilience | D19: 4 | E19: Watch only | F19: To review | I19: What slope failure mechanisms and early warning gaps are behind landslides that reach occupied homes on hillside sites? | J19: UA.NEWS | K19: 46321 | M19: Penang state authorities and Penang Municipal Council (MBPP) | N19: Malaysia | O19: Penang | P19: Paya Terubong landslide, Penang, Malaysia (Oct 2026) · Event · 7 reports | Q19: Russia | R19: 46321 | S19: 2026-Q4 | T19: landslide, collapse | U19: 5 | V19: https://news.google.com/rss/articles/CBMirwFBVV95cUxNdUtXS3JxY2xtSXRmMkdCNVY0V1lYazB4VlM5aDV5TGRxUTFuR2RZYVB5Z282YVJVSzZIQ3d0VHhOaDBRVU9WZUY0M2VQWEFRb2lfWmNLcEZRZ2U3RTNVOVVDM0NnWVVxc2NEdEpYRll1TDk5d3FkWXltZXVGa0N6Q1N4bEFVelBqY3BGb0xPSzRNMUJGdVRaR1g0bGJyS0paUElYZjBnanFQeTI2aVZN?oc=5 | W19: =IF($B19="",0,IF(AND(OR(OR(Dashboard!$B$5="All themes",Dashboard!$B$5=""),$C19=Dashboard!$B$5),OR(OR(Dashboard!$G$5="All uses",Dashboard!$G$5=""),$E19=Dashboard!$G$5),N($D19)>=Lists!$H$2,OR(OR(Dashboard!$N$5="All windows",Dashboard!$N$5=""),$S19=Dashboard!$N$5)),1,0)) | X19: =IF($W19=1,N($D19)*1E14+MIN(MAX(N($U19),0),9999)*1E10+MIN(N($K19),99999)*1E5+99999-MIN(ROW(),99999),"")
A20: 17 | B20: Fuerte oleaje provoca un socavón y daños en un malecón emblemático de México | C20: Offshore, Coasts & Water | D20: 4 | E20: Feature lead | F20: To review | I20: How do storm waves undermine the backfill behind a seafront promenade wall to create sinkholes, and what coastal protection and geotechnical checks should follow such damage? | J20: TV Azteca Jalisco | K20: 46321 | M20: Mazatlán municipal government and Sinaloa civil protection | N20: Mexico | O20: Mazatlán malecón, Sinaloa | P20: Mazatlán malecón wave sinkhole, Mexico (Oct 2026) · Event · 3 reports | Q20: Colombia | R20: 46319 | S20: 2026-Q4 | T20: sinkhole | U20: 4 | V20: https://news.google.com/rss/articles/CBMiywFBVV95cUxPTmRGcEVybWVjSzRpZ1pvMmZqdzBKQnJQVXR5YUpwNmVzclVUaGdnZVVhUXJlcHBVaGFSR1R0TXhKc3BTSXJuS1Ryc2FabjN1UlQyalJ2XzU3cTd4aTUxS0VOVkNfRnlIZXJFMld6UFNwVlVWVUwzWlRfX2trZk51aDNaUGpLeE9Td0xWYVJURTBFaVZlcm05bGxFWjNQZzJtekJNZFhrNmlfZEIxQmtzQjhndTlHclkxNldIbjBMMHhFMmlSOTNSbmlNdw?oc=5 | W20: =IF($B20="",0,IF(AND(OR(OR(Dashboard!$B$5="All themes",Dashboard!$B$5=""),$C20=Dashboard!$B$5),OR(OR(Dashboard!$G$5="All uses",Dashboard!$G$5=""),$E20=Dashboard!$G$5),N($D20)>=Lists!$H$2,OR(OR(Dashboard!$N$5="All windows",Dashboard!$N$5=""),$S20=Dashboard!$N$5)),1,0)) | X20: =IF($W20=1,N($D20)*1E14+MIN(MAX(N($U20),0),9999)*1E10+MIN(N($K20),99999)*1E5+99999-MIN(ROW(),99999),"")
A21: 18 | B21: Inician reparación de socavón provocado por fuerte oleaje junto al Monumento a la Mujer Mazatleca | C21: Offshore, Coasts & Water | D21: 4 | E21: Regional insight | F21: To review | I21: What repair approach suits a wave-undermined seafront structure, and how should designers balance scour protection, backfill compaction and monument stability at the shoreline? | J21: Los Noticieristas | K21: 46321 | M21: Mazatlán municipal government | N21: Mexico | O21: Monumento a la Mujer Mazatleca, Mazatlán | P21: Mazatlán malecón wave sinkhole, Mexico (Oct 2026) · Repair & reconstruction · 3 reports | Q21: Colombia | R21: 46318 | S21: 2026-Q4 | T21: sinkhole | U21: 4 | V21: https://news.google.com/rss/articles/CBMi5gFBVV95cUxPSnh3ZEx6N0ZTcnlzekRyS05rY2djbEVfZGs3cmttMkwxTU56V3pIbjNsanNsQ2FBdGtoMjZPdlRUcjNVZ2FyUVVrWUFsWGctMGVYQzYwTlBkQ0t0dm9UOEdkRkVSeTlkazBkUVdpNnVlbHRVU3hYNkZqdWRMVENoNWx0YXdybnRhWUttam5kX2FRUlJxMlRPS0ZIc09WUnRhSzNseDdSaWJLSEhrYWUtLWczUkNKZXJGQ2xOVE50OHBWVkZpZWZTdHE5QUVQQmpTcnY1OXVEVms4NXhpRjR5aEhRWDdpZw?oc=5 | W21: =IF($B21="",0,IF(AND(OR(OR(Dashboard!$B$5="All themes",Dashboard!$B$5=""),$C21=Dashboard!$B$5),OR(OR(Dashboard!$G$5="All uses",Dashboard!$G$5=""),$E21=Dashboard!$G$5),N($D21)>=Lists!$H$2,OR(OR(Dashboard!$N$5="All windows",Dashboard!$N$5=""),$S21=Dashboard!$N$5)),1,0)) | X21: =IF($W21=1,N($D21)*1E14+MIN(MAX(N($U21),0),9999)*1E10+MIN(N($K21),99999)*1E5+99999-MIN(ROW(),99999),"")
A22: 19 | B22: Ayuntamiento atiende más de 50 socavones su reparación cuesta hasta 700 mil pesos por punto | C22: Infrastructure & the Underground City | D22: 4 | E22: Feature lead | F22: To review | I22: Why do dozens of urban sinkholes appear in one city, and what are the economics and engineering options for locating leaking buried pipes and rehabilitating ground before repairs become recurrent? | J22: Pulso Diario San Luis | K22: 46321 | M22: San Luis Potosí municipal government | N22: Mexico | O22: San Luis Potosí city | Q22: Colombia | R22: 46320 | S22: 2026-Q4 | T22: sinkhole | U22: 4 | V22: https://news.google.com/rss/articles/CBMipAFBVV95cUxNUnM2My1keW1jZUFFWldaOGdueXdRemVGa21mVnNQU0w2bzRaalVPSWJVVGtCZms2OGkwcnlYTGR3ZzdaWG5UMjVOaXZhN2FSOVNzSVJKbHFBTU4wTEFSOTE5WVctQUhKdTR5bm1FQTQ3NDBJX2RsRWN5d2REVG9wOFJja0FOWUNGS0tvSjJFLUhwQ1BYR2dfMUQ3dzZMTWREVDZ5etIBqgFBVV95cUxOS2xrRXVVVlhvZUZLZkFpS1lWUTBsOVZHNHpyaUFiU2h6aE9Kdk1xeHUtR1ZRS3M0OFdQYzlWVzJwbjV5QTNydXNxT2xDMERONXBqQnVMZEZpSnVXdkFDcTU3ZVVOdXdKeEJVckFFRDlIT2hDaWdLdnZ0M19nNWdVZzhta3V2Mkt6bmt2RG9jRkwyaGVaMmYwZVVNTzNSR0VVNzZ3RGZ0ckl1UQ?oc=5 | W22: =IF($B22="",0,IF(AND(OR(OR(Dashboard!$B$5="All themes",Dashboard!$B$5=""),$C22=Dashboard!$B$5),OR(OR(Dashboard!$G$5="All uses",Dashboard!$G$5=""),$E22=Dashboard!$G$5),N($D22)>=Lists!$H$2,OR(OR(Dashboard!$N$5="All windows",Dashboard!$N$5=""),$S22=Dashboard!$N$5)),1,0)) | X22: =IF($W22=1,N($D22)*1E14+MIN(MAX(N($U22),0),9999)*1E10+MIN(N($K22),99999)*1E5+99999-MIN(ROW(),99999),"")
A23: 20 | B23: Ica: nuevo huaico podría repetir el bloqueo de la Panamericana Sur por falta de puente en Ocucaje | C23: Infrastructure & the Underground City | D23: 4 | E23: Feature lead | F23: To review | I23: How do debris flows crossing desert valleys threaten highway embankments and crossings, and what design choices should guide replacement of a missing bridge on this corridor? | J23: Diario Correo | K23: 46321 | M23: Provías Nacional (MTC) | N23: Peru | O23: Ocucaje, Ica | Q23: Peru | R23: 46320 | S23: 2026-Q4 | T23: debris flow | U23: 4 | V23: https://news.google.com/rss/articles/CBMi5AFBVV95cUxOb3NDdUN3Y3VHbl9BSE5xZUcwQkduTVRNdFQ0dlM1eUN3V0VyRzNYWDQxa0xaZjNUdkZjTmd4dHVBaTRCOXRCNUU3VTdTSnhGcms0X0dTMkZnMndqOEpWdFVDbXpUZWxGc2tJb0NkQ2JNMWV1dnBxR3BWYm5Ga1pRSGxMUDFuTkp1aEFyM1ozSHRkOVFFNkdGajNOZVJTSlp3OTBCT3d0NTFPMWJyemhtaGc4RmMzYWs3MWNvcHpIVHdsOXRuZF9HWnAyUGVLWGRkUW5jV2pPbVVnMzJ0bVRGY3ZDRljSAfgBQVVfeXFMUGk0TVN2aUMxUUhXYnN2SklCSmRvcm41R0pVSUNUV2s5Tkg4b1FEeldzbk13QVZsX3RjcFFobDlld1VrYzF6MnNJWVV6Y292WDhOSGZuMUdfV2E5OTdMamYwcWJTY0pHb2I4VzdsTWw1anBEWGVJanF1ejBpVHZVQnlBYzZOanhQb1lkTzVNYXJHbGttLVNNcG5oZnpzTFA2U2ZZYkNjNnl4MGxGMi11ZEZRUVNwZUpkTV9raVFVZGFHMWY2amVXd1VXRHB3Q0NIR1BCNmhBYmZ6X1VyVXBuNlhhQUFIR0NLd2dMNU11REotX0o3UWlPTlc?oc=5 | W23: =IF($B23="",0,IF(AND(OR(OR(Dashboard!$B$5="All themes",Dashboard!$B$5=""),$C23=Dashboard!$B$5),OR(OR(Dashboard!$G$5="All uses",Dashboard!$G$5=""),$E23=Dashboard!$G$5),N($D23)>=Lists!$H$2,OR(OR(Dashboard!$N$5="All windows",Dashboard!$N$5=""),$S23=Dashboard!$N$5)),1,0)) | X23: =IF($W23=1,N($D23)*1E14+MIN(MAX(N($U23),0),9999)*1E10+MIN(N($K23),99999)*1E5+99999-MIN(ROW(),99999),"")
A24: 21 | B24: Panamá interviene antigua mina de oro tras deslizamiento que amenaza fuentes de agua | C24: Hazards & Resilience | D24: 4 | E24: Feature lead | F24: To review | I24: How should slope and waste-material stability in an abandoned mine be assessed where failure threatens downstream water supplies? | J24: Infobae | K24: 46321 | M24: Panama's environment ministry (MiAmbiente) | N24: Panama | O24: former gold mine, Panama | Q24: Spain | R24: 46320 | S24: 2026-Q4 | T24: landslide | U24: 4 | V24: https://news.google.com/rss/articles/CBMixgFBVV95cUxQaVhsb1NSUXVneU1mZ0s1bXFVUHlEWjJrd0ZFa3FCeW1rYjVLeXBWcGxWSUJyM0VBaS00ZU9naFM4RGxYa1N0MUtGRlJMMExzZEJ2MXRoWnZnd3FCWHFwbFFna0xwUmhST3dab0NGNllRZGxyN1lENkJxVnhpa2RUcEdLWndtZmRySGw4RjlmU25ocmQ0aWJkQ1RUU0ZWSjlhZE9KYmpyUWhkOXdEbU9pc2RZc1dIVWxMQUloOGZCb3dWWDAxZnfSAeABQVVfeXFMUHV0bkZyU0hXY0RQTDdYd3g5M1d4QkxUYklYQlgxOFlGVjQyUTJwVVFVQTE3QUh6NzUtbVpfSkhjVW5kQlA5RW9nemlfNDBWQzJCRE9FY2xfZ19velh4a29NdkNlaEJJdGIwOGV3bW1zY1VCenhhd1VRRncybE9UM1YzU1ZrSzdWY0JTM1hVZVRmTDEySFFWWloxUEptSDV3MTVuOUdHTmFGZF9pRzBfM3E5YTNHSVkwNnRCc1NqMUU4LXl2SWlwMjByRWowN2FIc2lIb3ROWmVNZDRBeXpkY0g?oc=5 | W24: =IF($B24="",0,IF(AND(OR(OR(Dashboard!$B$5="All themes",Dashboard!$B$5=""),$C24=Dashboard!$B$5),OR(OR(Dashboard!$G$5="All uses",Dashboard!$G$5=""),$E24=Dashboard!$G$5),N($D24)>=Lists!$H$2,OR(OR(Dashboard!$N$5="All windows",Dashboard!$N$5=""),$S24=Dashboard!$N$5)),1,0)) | X24: =IF($W24=1,N($D24)*1E14+MIN(MAX(N($U24),0),9999)*1E10+MIN(N($K24),99999)*1E5+99999-MIN(ROW(),99999),"")
A25: 22 | B25: Socavón amenaza con dejar incomunicadas a dos barriadas en Arraiján | C25: Hazards & Resilience | D25: 4 | E25: Feature lead | F25: To review | I25: What causes a sinkhole to threaten access roads serving residential areas, and how should geotechnical investigation and emergency stabilisation be prioritised to keep communities connected? | J25: Telemetro | K25: 46321 | M25: Arraiján municipality and Panama's public works ministry (MOP) | N25: Panama | O25: Arraiján, Panamá Oeste | Q25: Colombia | R25: 46320 | S25: 2026-Q4 | T25: sinkhole | U25: 4 | V25: https://news.google.com/rss/articles/CBMipwFBVV95cUxPWHFDTVg5S1Z4YURHWFE5YjMycWRyYWNObmRLUVRMV0NsN2NGLU0zeUx6REd2NktKajNUOTdNZGxqcjNWWmE1NGk4WWUwck1DTUNvY0pOa2xGNDBIcWc1SURyXzFQZHpCbVQwY1JyMVpNRmVMdzgwd1VpQU53cm96cUNoM2pEQmJkQ2VBRVBtV1hpZkpDSE12aGNLYndSckl4V1ZTOG8tQdIBrAFBVV95cUxOMk93aGFZX1RCd045SlQ5d0gwOW9vOG1Sem5IYW9URVY3YTdOUnExWU80QlVnYU5wUDdaN1Y3SXlvS3pLT0FDcGxWbVc3N2ZPUXExVTU5LTZBNk01bFltYUVSTFQxSEZYMG9seXV3UUx2cXAyRUlFcHBLZTF6bmtIXzJHckt5Nld3TUJRbmJJTzBiTUMwQ1RabnhzR09hUUt6OXBoR3R5ZHY2MFl5?oc=5 | W25: =IF($B25="",0,IF(AND(OR(OR(Dashboard!$B$5="All themes",Dashboard!$B$5=""),$C25=Dashboard!$B$5),OR(OR(Dashboard!$G$5="All uses",Dashboard!$G$5=""),$E25=Dashboard!$G$5),N($D25)>=Lists!$H$2,OR(OR(Dashboard!$N$5="All windows",Dashboard!$N$5=""),$S25=Dashboard!$N$5)),1,0)) | X25: =IF($W25=1,N($D25)*1E14+MIN(MAX(N($U25),0),9999)*1E10+MIN(N($K25),99999)*1E5+99999-MIN(ROW(),99999),"")
A26: 23 | B26: Reportan caída de cuatro huéspedes en socavón de hotel Occidental de Cozumel | C26: Hazards & Resilience | D26: 4 | E26: News brief | F26: To review | I26: What subsurface conditions in coastal limestone, such as cenotes and dissolution cavities, lead to sudden ground collapse beneath resort buildings, and how should such sites be surveyed? | J26: Quinta Fuerza | K26: 46321 | M26: Hotel Occidental Cozumel management and Quintana Roo civil protection | N26: Mexico | O26: Cozumel, Quintana Roo | P26: Occidental Cozumel hotel sinkhole, Mexico (Oct 2026) · Event · 3 reports | Q26: Colombia | R26: 46320 | S26: 2026-Q4 | T26: sinkhole | U26: 4 | V26: https://news.google.com/rss/articles/CBMirwFBVV95cUxPVnhmNG5qb2FXNFprTmtzdnowYkYya3RTZ0I5VlZsWVJ3OTdsMWlkZ0hUcWlOQks1YWEycFhLWUlzZmhaREN3VUQ3REhuUklsX3k4M3J3QzFRbl9JaWduTlRqby1Rem4tYzhqUmtxUFVZU1BOQ25NTUxqZ1BOdzJzX3BYaklQaWV3NS1LbkdTY1ZhNGtSbkZrS2FabmpSWEtpY1BSV0t2S0hSZFYxOWVZ?oc=5 | W26: =IF($B26="",0,IF(AND(OR(OR(Dashboard!$B$5="All themes",Dashboard!$B$5=""),$C26=Dashboard!$B$5),OR(OR(Dashboard!$G$5="All uses",Dashboard!$G$5=""),$E26=Dashboard!$G$5),N($D26)>=Lists!$H$2,OR(OR(Dashboard!$N$5="All windows",Dashboard!$N$5=""),$S26=Dashboard!$N$5)),1,0)) | X26: =IF($W26=1,N($D26)*1E14+MIN(MAX(N($U26),0),9999)*1E10+MIN(N($K26),99999)*1E5+99999-MIN(ROW(),99999),"")
A27: 24 | B27: Alertas SMS, señaléticas y rutas de evacuación: el plan de La Reina ante futuros aluviones | C27: Hazards & Resilience | D27: 4 | E27: Feature lead | F27: To review | I27: Beyond warning systems, what ground-based hazard mapping and debris-flow control measures should a municipality in an Andean foothill commune use to plan evacuation and reduce aluvión exposure? | J27: Cooperativa | K27: 46321 | M27: La Reina municipality and Senapred | N27: Chile | O27: La Reina, Santiago | Q27: Chile | R27: 46319 | S27: 2026-Q4 | T27: debris flow | U27: 4 | V27: https://news.google.com/rss/articles/CBMi-wFBVV95cUxObzhjLXYxeEhDM0hkcVE1YVNRNzhhVGMtQmpuYlBnV0d2Ykk4XzR6QjJKdFR6Y3lsUjZrSlNYSW5fTnlFdHVtN21PT1NQZW5jS3FLMk9obEZ5cUxOLWlkcjlYTjA1VGo3aW9yY1VVaEdyUFVnNmhhZS1vNVdXLU1neDBzdlZYZGtGb3FnelhGZXVOUk56ZnRCQ2hqdmc5VWV0bUFxb1AwTHVRYWhQZ2hJamN1QTgzZExkdU5VdE0xWHp4OWJwQl91YkNDSlFwQ1hITm4xVl96Wm0yeVVEcHdCRXkxM3dVNEZDd19GRlNyUUxmZ0JZM0JLZE9YY9IBjAFBVV95cUxOck1uV2p6RDJ3VXVOVkI5ZVFtYzVuYkt1Tk1QVklFcHZCY3lDZVJ0cm1OWDh6VlpiMGlTaW53dElkUkNyRnE4VVlMYmRtSGR3YXItSTJ0RmZnWmt6UmR4anN5amw0emlSUU5NdHJoWVc2aHd3SU9kTVdjNGZQN29PanZLTk1GVndudnVqVA?oc=5 | W27: =IF($B27="",0,IF(AND(OR(OR(Dashboard!$B$5="All themes",Dashboard!$B$5=""),$C27=Dashboard!$B$5),OR(OR(Dashboard!$G$5="All uses",Dashboard!$G$5=""),$E27=Dashboard!$G$5),N($D27)>=Lists!$H$2,OR(OR(Dashboard!$N$5="All windows",Dashboard!$N$5=""),$S27=Dashboard!$N$5)),1,0)) | X27: =IF($W27=1,N($D27)*1E14+MIN(MAX(N($U27),0),9999)*1E10+MIN(N($K27),99999)*1E5+99999-MIN(ROW(),99999),"")
A28: 25 | B28: ANA instala 12 barreras para reducir el impacto de huaicos en Lima y Huarochirí | C28: Hazards & Resilience | D28: 4 | E28: Feature lead | F28: To review | I28: Can check dams and barrier structures in steep Andean gullies meaningfully reduce debris-flow impacts, and how should their design and maintenance be evaluated? | J28: TVPerú | K28: 46321 | M28: Autoridad Nacional del Agua (ANA) | N28: Peru | O28: Lima and Huarochirí | Q28: Peru | R28: 46320 | S28: 2026-Q4 | T28: debris flow | U28: 4 | V28: https://news.google.com/rss/articles/CBMiwwFBVV95cUxNWFA0THhERThMM2RnZS1WTWRDUVZOVUxEN254WUFHdEs5a0dfZGtINWtuOHAxM1I3TXRPak1xRDd0ZnZybEVWbF9BVnFaQVltSThXb3NHelk1ZVozMTAwcXJVMXF5cGZEREpPN2c3Z2gwNHNxSHVhZmlLNzluWGk1bERUTGlGVlJGejRLZVVIRDhfZ3VvSm9HaU41U1RZYkFLX2pJUlZoSE0yY0wtQ2FfdzMweXVIb29iWVJFUV9jclpNM3M?oc=5 | W28: =IF($B28="",0,IF(AND(OR(OR(Dashboard!$B$5="All themes",Dashboard!$B$5=""),$C28=Dashboard!$B$5),OR(OR(Dashboard!$G$5="All uses",Dashboard!$G$5=""),$E28=Dashboard!$G$5),N($D28)>=Lists!$H$2,OR(OR(Dashboard!$N$5="All windows",Dashboard!$N$5=""),$S28=Dashboard!$N$5)),1,0)) | X28: =IF($W28=1,N($D28)*1E14+MIN(MAX(N($U28),0),9999)*1E10+MIN(N($K28),99999)*1E5+99999-MIN(ROW(),99999),"")
A29: 26 | B29: Zero cycle: how Setl Group creates 3D excavation models for residential buildings using nanoCAD GeoniCS | C29: Digital Geotechnics | D29: 4 | E29: Feature lead | F29: To review | I29: How reliable are 3D excavation models built from site investigation data for deep pits in dense urban sites, and how should their accuracy be verified before construction? | J29: ComNews.ru | K29: 46321 | L29: Нулевой цикл: как в Setl Group создают 3D модели котлованов жилых зданий при помощи nanoCAD GeoniCS | M29: Setl Group (developer) and the nanoCAD GeoniCS software vendor | N29: Russia | Q29: Russia | R29: 46320 | S29: 2026-Q4 | T29: excavation | U29: 2 | V29: https://news.google.com/rss/articles/CBMi9wFBVV95cUxNb2RuOGhRdXFVMFdkZGFBRy0tQVZUWlMtODhEZzJpMzJicUFacnBWTXpkeEZ5YTdTMmxmbFNoUDRaWFdKVmdJZFJtbnJtc2p1ejBxbWR6OUs0ZkNSMlJhX0g4NEplZHdndFFITWVjeEF5bnNpZkNlTlBPWEFRN1FRNktCZXcyU1Fha1l4dXc3VHo0TVBsU3l0R2hob0NNYWtIeVM5YUNhVTNHWnAzUHozc0dsNmxLZUgtYzhpR2VubDdJMnF0aHNwdi0zd3JpXzI1Wk5hbDdyNnVmUERYQkFYSUV4UWRnR01GZXFIRVNENzZYTWpJSkFv?oc=5 | W29: =IF($B29="",0,IF(AND(OR(OR(Dashboard!$B$5="All themes",Dashboard!$B$5=""),$C29=Dashboard!$B$5),OR(OR(Dashboard!$G$5="All uses",Dashboard!$G$5=""),$E29=Dashboard!$G$5),N($D29)>=Lists!$H$2,OR(OR(Dashboard!$N$5="All windows",Dashboard!$N$5=""),$S29=Dashboard!$N$5)),1,0)) | X29: =IF($W29=1,N($D29)*1E14+MIN(MAX(N($U29),0),9999)*1E10+MIN(N($K29),99999)*1E5+99999-MIN(ROW(),99999),"")
A30: 27 | B30: Anuncia Ayuntamiento de Cuernavaca cierre temporal de Avenida Universidad por revisión de hundimiento | C30: Infrastructure & the Underground City | D30: 4 | E30: News brief | F30: To review | I30: What ground or utility causes are behind the subsidence on Avenida Universidad, and what investigation should determine whether the road can safely reopen? | J30: La Jornada Morelos | K30: 46321 | M30: the Cuernavaca city council | N30: Mexico | O30: Avenida Universidad, Cuernavaca | Q30: Argentina | R30: 46319 | S30: 2026-Q4 | U30: 0 | V30: https://news.google.com/rss/articles/CBMi2wFBVV95cUxPMTNJeGdhN2Y2Q0lMTlZlU2UzUHNVTW9udUMwWEZXZEJiYThReDRFODE5NmRlZE1vTXFfOU5zV1FwcFVYVV9pRGFmT29SWDZ0Ulk0R0ZEbWZDdlB5RTBuSXRHSndyMDA3QlliNmNRajRoUjBscGdWVFRRVFdNRFdvTVBvSUZlMjVYSWV4NkhnTFkyeG5wRmdZVmgweGV6LUp3X045OVJsZ3F2ajRRa2ZUeWFMdEFGX0szZlBnel9ZUkNrdkRYcWRzbUZUZ0t4WTZBTUVnLWpBRjVrcG8?oc=5 | W30: =IF($B30="",0,IF(AND(OR(OR(Dashboard!$B$5="All themes",Dashboard!$B$5=""),$C30=Dashboard!$B$5),OR(OR(Dashboard!$G$5="All uses",Dashboard!$G$5=""),$E30=Dashboard!$G$5),N($D30)>=Lists!$H$2,OR(OR(Dashboard!$N$5="All windows",Dashboard!$N$5=""),$S30=Dashboard!$N$5)),1,0)) | X30: =IF($W30=1,N($D30)*1E14+MIN(MAX(N($U30),0),9999)*1E10+MIN(N($K30),99999)*1E5+99999-MIN(ROW(),99999),"")
A31: 28 | B31: India's first bullet train: station to be built 100 feet underground, high-speed train to pass beneath the sea | C31: Infrastructure & the Underground City | D31: 4 | E31: Feature lead | F31: To review | I31: What ground conditions and deep excavation methods are needed for a 30 m deep station and an undersea tunnel on India's first bullet train route? | J31: Inh News | K31: 46321 | L31: भारत की पहली बुलेट ट्रेन: 100 फीट नीचे बनेगा स्टेशन, समुद्र के नीचे से गुजरेगी हाई-स्पीड ट्रेन | M31: NHSRCL (National High Speed Rail Corporation) | N31: India | O31: Mumbai–Ahmedabad bullet train corridor | Q31: India | R31: 46320 | S31: 2026-Q4 | U31: 0 | V31: https://news.google.com/rss/articles/CBMijwFBVV95cUxOZGhPdS0zY1BmbHVzOUNQZWR0dkZCZ1VuRVh3NV9mbF8wdGY5aVEwTjhNdkIzdTlnM2cyWmZCUDdIdzVab1hFd3ZNZjdsUWlVc0I1Z2xyVHhEbHFGRUtNTWp2dVZIREx6aG5ZaHlXQ3hwdC1lb29YYllJbzNxZ29LX1ppUFN6a2w2WHdZaTlkY9IBlAFBVV95cUxNakMwc3pUZG5mUlZjWVZPa1VyNG5UN3U2NTkzRGRENXZpNUJSZThYZ1lJNGVjUnZvLU90Zm5rdVpEa2tLMmtVUlB1bUhSSjhtalpjZlhXQ0phYnFCdWRLOFo3cmJtZWtKVDRETlhYSWVaRzBRTEZiNHhvNUxVZDUwTGo0MlNvVVlLeW5oY3R6aVF6bldL?oc=5 | W31: =IF($B31="",0,IF(AND(OR(OR(Dashboard!$B$5="All themes",Dashboard!$B$5=""),$C31=Dashboard!$B$5),OR(OR(Dashboard!$G$5="All uses",Dashboard!$G$5=""),$E31=Dashboard!$G$5),N($D31)>=Lists!$H$2,OR(OR(Dashboard!$N$5="All windows",Dashboard!$N$5=""),$S31=Dashboard!$N$5)),1,0)) | X31: =IF($W31=1,N($D31)*1E14+MIN(MAX(N($U31),0),9999)*1E10+MIN(N($K31),99999)*1E5+99999-MIN(ROW(),99999),"")
