Workbook

Sheet Start here
B1: Geotechnical News · Whole archive
B2: All 1 issue windows · generated 24 Oct 2026
B5: This workbook holds 30 stories from 1 daily digest, 24 Oct 2026 to 24 Oct 2026, in 5 themes and from 23 sources.
B7: What is in this workbook
B8: Dashboard → | C8: Key figures, the Top 10 stories, charts by theme, use, relevance and planning status, a theme × use heat map and a timeline. Choose what it shows with the yellow selectors at the top.
B9: Stories → | C9: Every story as a filterable Excel table, newest digest first; click a headline to open the article. The gold columns – Status, Assigned to and Editor notes – are for you to fill in.
B10: By theme → | C10: A read-only reading view: one section per theme, best stories first. Collapse or expand sections with the − / + buttons in the left margin.
B11: Sources → | C11: The outlets that supplied stories: how many, average relevance, main theme and how many match the current Dashboard selection.
B13: How to use the Dashboard selectors
B14: 1 | C14: Open the Dashboard. The yellow boxes at the top are selectors: Theme, Suggested use, Minimum relevance and Issue window.
B15: 2 | C15: Click a yellow box, then the ▼ arrow that appears beside it, and pick a value. Choose “All …” or “Any” to clear that selector.
B16: 3 | C16: The key figures, tables, charts, heat map and the Top 10 list recalculate at once. Headlines in the Top 10 open the article.
B17: 4 | C17: In Stories, set each story’s Status as you plan the issue. The Dashboard’s Planning status table and chart, and the PLANNED figure, count them straight away.
B18: 5 | C18: Filters in the Stories table (▼ in its header) only hide rows; the Dashboard follows the selectors. To list exactly what the Dashboard shows, filter the ‘In Dashboard selection’ column of Stories to ✓.
B20: Planning status (Stories › Status)
B21: To review | C21: New from the scan, not looked at yet (every story starts here)
B22: Shortlisted | C22: Worth considering for the issue
B23: Commissioned | C23: A writer or contributor has been asked to cover it
B24: Published | C24: Used in a published issue or newsletter
B25: Not used | C25: Reviewed and set aside
B27: Relevance scale (AI triage)
B28: 5 / 5 | C28: Rich geotechnical lesson or a major ground-related event
B29: 4 / 5 | C29: Strong ground-engineering content
B30: 3 / 5 | C30: Clear ground-engineering element, worth a brief
B31: 2 / 5 | C31: Weak link to geotechnics
B32: 1 / 5 | C32: Not really geotechnical
B33: – | C33: Shown as –. Not rated by AI: ranked on keyword matches only
B35: Jump to a theme (opens its section in By theme)
B36: Digital Geotechnics | C36: 1 story · 1 rated 5 / 5 · 0 feature leads
B37: Hazards & Resilience | C37: 18 stories · 0 rated 5 / 5 · 6 feature leads
B38: Infrastructure & the Underground City | C38: 5 stories · 0 rated 5 / 5 · 2 feature leads
B39: Characterisation & Modelling | C39: 4 stories · 0 rated 5 / 5 · 3 feature leads
B40: Geotechnics & Society | C40: 2 stories · 0 rated 5 / 5 · 0 feature leads
B41: No stories yet | C41: Sustainability & the Energy Transition, Ground Improvement & Innovation, Offshore, Coasts & Water, General
B43: Good to know
B44: Blank figures? | C44: The Dashboard is calculated when the file opens. If it shows blanks or zeros in Excel, click Enable Editing in the yellow bar at the top (files from the internet open in Protected View); in LibreOffice press Ctrl+Shift+F9.
B45: Your edits | C45: This file is generated again after every scan. Status, Assigned to and Editor notes are kept only in the copy you save, so keep one working copy per issue.
B46: Lists sheet | C46: A hidden sheet holds the values offered by the dropdowns and some helper cells. There is no need to change it.

Sheet Dashboard
B1: Geotechnical News · Whole archive
B2: All 1 issue windows · generated 24 Oct 2026
B4: THEME | G4: SUGGESTED USE | K4: MINIMUM RELEVANCE (OUT OF 5) | N4: ISSUE WINDOW | Q4: Tip: click a yellow box, then its ▼ arrow, to choose. Pick “All …” or “Any” to clear it. Everything below updates.
B5: All themes | G5: All uses | K5: Any | N5: All windows
B6: ="Showing "&Lists!$H$6&" of "&Lists!$H$4&" stories"&IF(Lists!$H$5," – no selector set."," for the selection above. Set every box back to All / Any to see everything.")
B8: =Lists!$H$6 | E8: =IF(Lists!$H$5,Lists!$H$3,COUNTIF(Lists!$K$2:$K$2,">0")) | H8: =COUNTIFS(Stories!$T$4:$T$33,1,Stories!$D$4:$D$33,5) | K8: =COUNTIFS(Stories!$T$4:$T$33,1,Stories!$E$4:$E$33,"Feature lead") | N8: =COUNTIFS(Stories!$T$4:$T$33,1,Stories!$F$4:$F$33,"Shortlisted")+COUNTIFS(Stories!$T$4:$T$33,1,Stories!$F$4:$F$33,"Commissioned")+COUNTIFS(Stories!$T$4:$T$33,1,Stories!$F$4:$F$33,"Published") | Q8: =COUNTIF(Sources!$C$4:$C$26,">0")
B9: STORIES | E9: =IF(Lists!$H$5,"DAILY DIGESTS","DIGESTS WITH MATCHES") | H9: RATED 5 / 5 | K9: FEATURE LEADS | N9: PLANNED | Q9: SOURCES
B10: ="of "&Lists!$H$4&" in this workbook" | E10: =IF(Lists!$H$5,"scans in this period","of "&Lists!$H$3&" scans in this period") | H10: ="rated 4 / 5: "&COUNTIFS(Stories!$T$4:$T$33,1,Stories!$D$4:$D$33,4) | K10: ="news briefs: "&COUNTIFS(Stories!$T$4:$T$33,1,Stories!$E$4:$E$33,"News brief") | N10: ="shortlisted or later · to review: "&COUNTIFS(Stories!$T$4:$T$33,1,Stories!$F$4:$F$33,"To review") | Q10: ="of 23 outlets in this workbook"
B12: Top 10 stories for this selection
B13: # | C13: Headline (click to open the article) | I13: Digest | J13: Theme | M13: Relevance | N13: Suggested use | P13: Source | R13: Story No. | S13: Status
B14: =IF(Lists!$O$2="","",1) | C14: =IF(Lists!$O$2="","No stories match this selection – choose “All …” or “Any” in a box above.",IF(AND(Lists!$P$2<>"",LEN(Lists!$P$2)<=255),HYPERLINK(Lists!$P$2,Lists!$Q$2),HYPERLINK("#'Stories'!B"&(Lists!$O$2+3),Lists!$Q$2))) | I14: =IF(Lists!$O$2="","",INDEX(Stories!$K$4:$K$33,Lists!$O$2)) | J14: =IF(Lists!$O$2="","",INDEX(Stories!$C$4:$C$33,Lists!$O$2)&"") | M14: =IF(Lists!$O$2="","",INDEX(Stories!$D$4:$D$33,Lists!$O$2)) | N14: =IF(Lists!$O$2="","",INDEX(Stories!$E$4:$E$33,Lists!$O$2)&"") | P14: =IF(Lists!$O$2="","",INDEX(Stories!$J$4:$J$33,Lists!$O$2)&"") | R14: =IF(Lists!$O$2="","",INDEX(Stories!$A$4:$A$33,Lists!$O$2)) | S14: =IF(Lists!$O$2="","",INDEX(Stories!$F$4:$F$33,Lists!$O$2)&"")
B15: =IF(Lists!$O$3="","",2) | C15: =IF(Lists!$O$3="","",IF(AND(Lists!$P$3<>"",LEN(Lists!$P$3)<=255),HYPERLINK(Lists!$P$3,Lists!$Q$3),HYPERLINK("#'Stories'!B"&(Lists!$O$3+3),Lists!$Q$3))) | I15: =IF(Lists!$O$3="","",INDEX(Stories!$K$4:$K$33,Lists!$O$3)) | J15: =IF(Lists!$O$3="","",INDEX(Stories!$C$4:$C$33,Lists!$O$3)&"") | M15: =IF(Lists!$O$3="","",INDEX(Stories!$D$4:$D$33,Lists!$O$3)) | N15: =IF(Lists!$O$3="","",INDEX(Stories!$E$4:$E$33,Lists!$O$3)&"") | P15: =IF(Lists!$O$3="","",INDEX(Stories!$J$4:$J$33,Lists!$O$3)&"") | R15: =IF(Lists!$O$3="","",INDEX(Stories!$A$4:$A$33,Lists!$O$3)) | S15: =IF(Lists!$O$3="","",INDEX(Stories!$F$4:$F$33,Lists!$O$3)&"")
B16: =IF(Lists!$O$4="","",3) | C16: =IF(Lists!$O$4="","",IF(AND(Lists!$P$4<>"",LEN(Lists!$P$4)<=255),HYPERLINK(Lists!$P$4,Lists!$Q$4),HYPERLINK("#'Stories'!B"&(Lists!$O$4+3),Lists!$Q$4))) | I16: =IF(Lists!$O$4="","",INDEX(Stories!$K$4:$K$33,Lists!$O$4)) | J16: =IF(Lists!$O$4="","",INDEX(Stories!$C$4:$C$33,Lists!$O$4)&"") | M16: =IF(Lists!$O$4="","",INDEX(Stories!$D$4:$D$33,Lists!$O$4)) | N16: =IF(Lists!$O$4="","",INDEX(Stories!$E$4:$E$33,Lists!$O$4)&"") | P16: =IF(Lists!$O$4="","",INDEX(Stories!$J$4:$J$33,Lists!$O$4)&"") | R16: =IF(Lists!$O$4="","",INDEX(Stories!$A$4:$A$33,Lists!$O$4)) | S16: =IF(Lists!$O$4="","",INDEX(Stories!$F$4:$F$33,Lists!$O$4)&"")
B17: =IF(Lists!$O$5="","",4) | C17: =IF(Lists!$O$5="","",IF(AND(Lists!$P$5<>"",LEN(Lists!$P$5)<=255),HYPERLINK(Lists!$P$5,Lists!$Q$5),HYPERLINK("#'Stories'!B"&(Lists!$O$5+3),Lists!$Q$5))) | I17: =IF(Lists!$O$5="","",INDEX(Stories!$K$4:$K$33,Lists!$O$5)) | J17: =IF(Lists!$O$5="","",INDEX(Stories!$C$4:$C$33,Lists!$O$5)&"") | M17: =IF(Lists!$O$5="","",INDEX(Stories!$D$4:$D$33,Lists!$O$5)) | N17: =IF(Lists!$O$5="","",INDEX(Stories!$E$4:$E$33,Lists!$O$5)&"") | P17: =IF(Lists!$O$5="","",INDEX(Stories!$J$4:$J$33,Lists!$O$5)&"") | R17: =IF(Lists!$O$5="","",INDEX(Stories!$A$4:$A$33,Lists!$O$5)) | S17: =IF(Lists!$O$5="","",INDEX(Stories!$F$4:$F$33,Lists!$O$5)&"")
B18: =IF(Lists!$O$6="","",5) | C18: =IF(Lists!$O$6="","",IF(AND(Lists!$P$6<>"",LEN(Lists!$P$6)<=255),HYPERLINK(Lists!$P$6,Lists!$Q$6),HYPERLINK("#'Stories'!B"&(Lists!$O$6+3),Lists!$Q$6))) | I18: =IF(Lists!$O$6="","",INDEX(Stories!$K$4:$K$33,Lists!$O$6)) | J18: =IF(Lists!$O$6="","",INDEX(Stories!$C$4:$C$33,Lists!$O$6)&"") | M18: =IF(Lists!$O$6="","",INDEX(Stories!$D$4:$D$33,Lists!$O$6)) | N18: =IF(Lists!$O$6="","",INDEX(Stories!$E$4:$E$33,Lists!$O$6)&"") | P18: =IF(Lists!$O$6="","",INDEX(Stories!$J$4:$J$33,Lists!$O$6)&"") | R18: =IF(Lists!$O$6="","",INDEX(Stories!$A$4:$A$33,Lists!$O$6)) | S18: =IF(Lists!$O$6="","",INDEX(Stories!$F$4:$F$33,Lists!$O$6)&"")
B19: =IF(Lists!$O$7="","",6) | C19: =IF(Lists!$O$7="","",IF(AND(Lists!$P$7<>"",LEN(Lists!$P$7)<=255),HYPERLINK(Lists!$P$7,Lists!$Q$7),HYPERLINK("#'Stories'!B"&(Lists!$O$7+3),Lists!$Q$7))) | I19: =IF(Lists!$O$7="","",INDEX(Stories!$K$4:$K$33,Lists!$O$7)) | J19: =IF(Lists!$O$7="","",INDEX(Stories!$C$4:$C$33,Lists!$O$7)&"") | M19: =IF(Lists!$O$7="","",INDEX(Stories!$D$4:$D$33,Lists!$O$7)) | N19: =IF(Lists!$O$7="","",INDEX(Stories!$E$4:$E$33,Lists!$O$7)&"") | P19: =IF(Lists!$O$7="","",INDEX(Stories!$J$4:$J$33,Lists!$O$7)&"") | R19: =IF(Lists!$O$7="","",INDEX(Stories!$A$4:$A$33,Lists!$O$7)) | S19: =IF(Lists!$O$7="","",INDEX(Stories!$F$4:$F$33,Lists!$O$7)&"")
B20: =IF(Lists!$O$8="","",7) | C20: =IF(Lists!$O$8="","",IF(AND(Lists!$P$8<>"",LEN(Lists!$P$8)<=255),HYPERLINK(Lists!$P$8,Lists!$Q$8),HYPERLINK("#'Stories'!B"&(Lists!$O$8+3),Lists!$Q$8))) | I20: =IF(Lists!$O$8="","",INDEX(Stories!$K$4:$K$33,Lists!$O$8)) | J20: =IF(Lists!$O$8="","",INDEX(Stories!$C$4:$C$33,Lists!$O$8)&"") | M20: =IF(Lists!$O$8="","",INDEX(Stories!$D$4:$D$33,Lists!$O$8)) | N20: =IF(Lists!$O$8="","",INDEX(Stories!$E$4:$E$33,Lists!$O$8)&"") | P20: =IF(Lists!$O$8="","",INDEX(Stories!$J$4:$J$33,Lists!$O$8)&"") | R20: =IF(Lists!$O$8="","",INDEX(Stories!$A$4:$A$33,Lists!$O$8)) | S20: =IF(Lists!$O$8="","",INDEX(Stories!$F$4:$F$33,Lists!$O$8)&"")
B21: =IF(Lists!$O$9="","",8) | C21: =IF(Lists!$O$9="","",IF(AND(Lists!$P$9<>"",LEN(Lists!$P$9)<=255),HYPERLINK(Lists!$P$9,Lists!$Q$9),HYPERLINK("#'Stories'!B"&(Lists!$O$9+3),Lists!$Q$9))) | I21: =IF(Lists!$O$9="","",INDEX(Stories!$K$4:$K$33,Lists!$O$9)) | J21: =IF(Lists!$O$9="","",INDEX(Stories!$C$4:$C$33,Lists!$O$9)&"") | M21: =IF(Lists!$O$9="","",INDEX(Stories!$D$4:$D$33,Lists!$O$9)) | N21: =IF(Lists!$O$9="","",INDEX(Stories!$E$4:$E$33,Lists!$O$9)&"") | P21: =IF(Lists!$O$9="","",INDEX(Stories!$J$4:$J$33,Lists!$O$9)&"") | R21: =IF(Lists!$O$9="","",INDEX(Stories!$A$4:$A$33,Lists!$O$9)) | S21: =IF(Lists!$O$9="","",INDEX(Stories!$F$4:$F$33,Lists!$O$9)&"")
B22: =IF(Lists!$O$10="","",9) | C22: =IF(Lists!$O$10="","",IF(AND(Lists!$P$10<>"",LEN(Lists!$P$10)<=255),HYPERLINK(Lists!$P$10,Lists!$Q$10),HYPERLINK("#'Stories'!B"&(Lists!$O$10+3),Lists!$Q$10))) | I22: =IF(Lists!$O$10="","",INDEX(Stories!$K$4:$K$33,Lists!$O$10)) | J22: =IF(Lists!$O$10="","",INDEX(Stories!$C$4:$C$33,Lists!$O$10)&"") | M22: =IF(Lists!$O$10="","",INDEX(Stories!$D$4:$D$33,Lists!$O$10)) | N22: =IF(Lists!$O$10="","",INDEX(Stories!$E$4:$E$33,Lists!$O$10)&"") | P22: =IF(Lists!$O$10="","",INDEX(Stories!$J$4:$J$33,Lists!$O$10)&"") | R22: =IF(Lists!$O$10="","",INDEX(Stories!$A$4:$A$33,Lists!$O$10)) | S22: =IF(Lists!$O$10="","",INDEX(Stories!$F$4:$F$33,Lists!$O$10)&"")
B23: =IF(Lists!$O$11="","",10) | C23: =IF(Lists!$O$11="","",IF(AND(Lists!$P$11<>"",LEN(Lists!$P$11)<=255),HYPERLINK(Lists!$P$11,Lists!$Q$11),HYPERLINK("#'Stories'!B"&(Lists!$O$11+3),Lists!$Q$11))) | I23: =IF(Lists!$O$11="","",INDEX(Stories!$K$4:$K$33,Lists!$O$11)) | J23: =IF(Lists!$O$11="","",INDEX(Stories!$C$4:$C$33,Lists!$O$11)&"") | M23: =IF(Lists!$O$11="","",INDEX(Stories!$D$4:$D$33,Lists!$O$11)) | N23: =IF(Lists!$O$11="","",INDEX(Stories!$E$4:$E$33,Lists!$O$11)&"") | P23: =IF(Lists!$O$11="","",INDEX(Stories!$J$4:$J$33,Lists!$O$11)&"") | R23: =IF(Lists!$O$11="","",INDEX(Stories!$A$4:$A$33,Lists!$O$11)) | S23: =IF(Lists!$O$11="","",INDEX(Stories!$F$4:$F$33,Lists!$O$11)&"")
C24: Ranked by relevance, then keyword score, then newest digest. Find a story in the Stories sheet by its Story No.
B26: Stories by theme
B27: Theme | F27: Stories | G27: Rated 5 | H27: Rated 4 | I27: Feature leads | J27: Share
B28: Sustainability & the Energy Transition | F28: =SUMPRODUCT(Stories!$T$4:$T$33,--(Stories!$C$4:$C$33=$B28)) | G28: =SUMPRODUCT(Stories!$T$4:$T$33,--(Stories!$C$4:$C$33=$B28),--(Stories!$D$4:$D$33=5)) | H28: =SUMPRODUCT(Stories!$T$4:$T$33,--(Stories!$C$4:$C$33=$B28),--(Stories!$D$4:$D$33=4)) | I28: =SUMPRODUCT(Stories!$T$4:$T$33,--(Stories!$C$4:$C$33=$B28),--(Stories!$E$4:$E$33="Feature lead")) | J28: =IF(Lists!$H$6=0,0,F28/Lists!$H$6)
B29: Digital Geotechnics | F29: =SUMPRODUCT(Stories!$T$4:$T$33,--(Stories!$C$4:$C$33=$B29)) | G29: =SUMPRODUCT(Stories!$T$4:$T$33,--(Stories!$C$4:$C$33=$B29),--(Stories!$D$4:$D$33=5)) | H29: =SUMPRODUCT(Stories!$T$4:$T$33,--(Stories!$C$4:$C$33=$B29),--(Stories!$D$4:$D$33=4)) | I29: =SUMPRODUCT(Stories!$T$4:$T$33,--(Stories!$C$4:$C$33=$B29),--(Stories!$E$4:$E$33="Feature lead")) | J29: =IF(Lists!$H$6=0,0,F29/Lists!$H$6)
B30: Hazards & Resilience | F30: =SUMPRODUCT(Stories!$T$4:$T$33,--(Stories!$C$4:$C$33=$B30)) | G30: =SUMPRODUCT(Stories!$T$4:$T$33,--(Stories!$C$4:$C$33=$B30),--(Stories!$D$4:$D$33=5)) | H30: =SUMPRODUCT(Stories!$T$4:$T$33,--(Stories!$C$4:$C$33=$B30),--(Stories!$D$4:$D$33=4)) | I30: =SUMPRODUCT(Stories!$T$4:$T$33,--(Stories!$C$4:$C$33=$B30),--(Stories!$E$4:$E$33="Feature lead")) | J30: =IF(Lists!$H$6=0,0,F30/Lists!$H$6)
B31: Ground Improvement & Innovation | F31: =SUMPRODUCT(Stories!$T$4:$T$33,--(Stories!$C$4:$C$33=$B31)) | G31: =SUMPRODUCT(Stories!$T$4:$T$33,--(Stories!$C$4:$C$33=$B31),--(Stories!$D$4:$D$33=5)) | H31: =SUMPRODUCT(Stories!$T$4:$T$33,--(Stories!$C$4:$C$33=$B31),--(Stories!$D$4:$D$33=4)) | I31: =SUMPRODUCT(Stories!$T$4:$T$33,--(Stories!$C$4:$C$33=$B31),--(Stories!$E$4:$E$33="Feature lead")) | J31: =IF(Lists!$H$6=0,0,F31/Lists!$H$6)
B32: Infrastructure & the Underground City | F32: =SUMPRODUCT(Stories!$T$4:$T$33,--(Stories!$C$4:$C$33=$B32)) | G32: =SUMPRODUCT(Stories!$T$4:$T$33,--(Stories!$C$4:$C$33=$B32),--(Stories!$D$4:$D$33=5)) | H32: =SUMPRODUCT(Stories!$T$4:$T$33,--(Stories!$C$4:$C$33=$B32),--(Stories!$D$4:$D$33=4)) | I32: =SUMPRODUCT(Stories!$T$4:$T$33,--(Stories!$C$4:$C$33=$B32),--(Stories!$E$4:$E$33="Feature lead")) | J32: =IF(Lists!$H$6=0,0,F32/Lists!$H$6)
B33: Offshore, Coasts & Water | F33: =SUMPRODUCT(Stories!$T$4:$T$33,--(Stories!$C$4:$C$33=$B33)) | G33: =SUMPRODUCT(Stories!$T$4:$T$33,--(Stories!$C$4:$C$33=$B33),--(Stories!$D$4:$D$33=5)) | H33: =SUMPRODUCT(Stories!$T$4:$T$33,--(Stories!$C$4:$C$33=$B33),--(Stories!$D$4:$D$33=4)) | I33: =SUMPRODUCT(Stories!$T$4:$T$33,--(Stories!$C$4:$C$33=$B33),--(Stories!$E$4:$E$33="Feature lead")) | J33: =IF(Lists!$H$6=0,0,F33/Lists!$H$6)
B34: Characterisation & Modelling | F34: =SUMPRODUCT(Stories!$T$4:$T$33,--(Stories!$C$4:$C$33=$B34)) | G34: =SUMPRODUCT(Stories!$T$4:$T$33,--(Stories!$C$4:$C$33=$B34),--(Stories!$D$4:$D$33=5)) | H34: =SUMPRODUCT(Stories!$T$4:$T$33,--(Stories!$C$4:$C$33=$B34),--(Stories!$D$4:$D$33=4)) | I34: =SUMPRODUCT(Stories!$T$4:$T$33,--(Stories!$C$4:$C$33=$B34),--(Stories!$E$4:$E$33="Feature lead")) | J34: =IF(Lists!$H$6=0,0,F34/Lists!$H$6)
B35: Geotechnics & Society | F35: =SUMPRODUCT(Stories!$T$4:$T$33,--(Stories!$C$4:$C$33=$B35)) | G35: =SUMPRODUCT(Stories!$T$4:$T$33,--(Stories!$C$4:$C$33=$B35),--(Stories!$D$4:$D$33=5)) | H35: =SUMPRODUCT(Stories!$T$4:$T$33,--(Stories!$C$4:$C$33=$B35),--(Stories!$D$4:$D$33=4)) | I35: =SUMPRODUCT(Stories!$T$4:$T$33,--(Stories!$C$4:$C$33=$B35),--(Stories!$E$4:$E$33="Feature lead")) | J35: =IF(Lists!$H$6=0,0,F35/Lists!$H$6)
B36: General | F36: =SUMPRODUCT(Stories!$T$4:$T$33,--(Stories!$C$4:$C$33=$B36)) | G36: =SUMPRODUCT(Stories!$T$4:$T$33,--(Stories!$C$4:$C$33=$B36),--(Stories!$D$4:$D$33=5)) | H36: =SUMPRODUCT(Stories!$T$4:$T$33,--(Stories!$C$4:$C$33=$B36),--(Stories!$D$4:$D$33=4)) | I36: =SUMPRODUCT(Stories!$T$4:$T$33,--(Stories!$C$4:$C$33=$B36),--(Stories!$E$4:$E$33="Feature lead")) | J36: =IF(Lists!$H$6=0,0,F36/Lists!$H$6)
B38: Suggested editorial use | H38: Geotechnical relevance | N38: Planning status
B39: Use | E39: Stories | F39: Share | H39: Relevance | K39: Stories | L39: Share | N39: Status | Q39: Stories | R39: Share
B40: Feature lead | E40: =SUMPRODUCT(Stories!$T$4:$T$33,--(Stories!$E$4:$E$33=$B40)) | F40: =IF(Lists!$H$6=0,0,E40/Lists!$H$6) | H40: 5 / 5 | K40: =COUNTIFS(Stories!$T$4:$T$33,1,Stories!$D$4:$D$33,5) | L40: =IF(Lists!$H$6=0,0,K40/Lists!$H$6) | N40: To review | Q40: =COUNTIFS(Stories!$T$4:$T$33,1,Stories!$F$4:$F$33,"To review") | R40: =IF(Lists!$H$6=0,0,Q40/Lists!$H$6)
B41: News brief | E41: =SUMPRODUCT(Stories!$T$4:$T$33,--(Stories!$E$4:$E$33=$B41)) | F41: =IF(Lists!$H$6=0,0,E41/Lists!$H$6) | H41: 4 / 5 | K41: =COUNTIFS(Stories!$T$4:$T$33,1,Stories!$D$4:$D$33,4) | L41: =IF(Lists!$H$6=0,0,K41/Lists!$H$6) | N41: Shortlisted | Q41: =COUNTIFS(Stories!$T$4:$T$33,1,Stories!$F$4:$F$33,"Shortlisted") | R41: =IF(Lists!$H$6=0,0,Q41/Lists!$H$6)
B42: Academia-to-Industry topic | E42: =SUMPRODUCT(Stories!$T$4:$T$33,--(Stories!$E$4:$E$33=$B42)) | F42: =IF(Lists!$H$6=0,0,E42/Lists!$H$6) | H42: 3 / 5 | K42: =COUNTIFS(Stories!$T$4:$T$33,1,Stories!$D$4:$D$33,3) | L42: =IF(Lists!$H$6=0,0,K42/Lists!$H$6) | N42: Commissioned | Q42: =COUNTIFS(Stories!$T$4:$T$33,1,Stories!$F$4:$F$33,"Commissioned") | R42: =IF(Lists!$H$6=0,0,Q42/Lists!$H$6)
B43: Regional insight | E43: =SUMPRODUCT(Stories!$T$4:$T$33,--(Stories!$E$4:$E$33=$B43)) | F43: =IF(Lists!$H$6=0,0,E43/Lists!$H$6) | N43: Published | Q43: =COUNTIFS(Stories!$T$4:$T$33,1,Stories!$F$4:$F$33,"Published") | R43: =IF(Lists!$H$6=0,0,Q43/Lists!$H$6)
B44: Watch only | E44: =SUMPRODUCT(Stories!$T$4:$T$33,--(Stories!$E$4:$E$33=$B44)) | F44: =IF(Lists!$H$6=0,0,E44/Lists!$H$6) | N44: Not used | Q44: =COUNTIFS(Stories!$T$4:$T$33,1,Stories!$F$4:$F$33,"Not used") | R44: =IF(Lists!$H$6=0,0,Q44/Lists!$H$6)
B59: Theme × suggested use (heat map for this selection)
...

Sheet Stories
A1: Stories · 30 in this workbook | C1: ← Dashboard | D1: ↑ Start here | E1: By theme →
C2: Gold columns are yours: choose a Status from its dropdown, and fill in Assigned to and Editor notes. Use ▼ in the header to filter or sort. ✓ in ‘In Dashboard selection’ (far right) marks the stories the Dashboard is showing.
A3: No. | B3: Headline (English) | C3: Theme | D3: Relevance | E3: Suggested use | F3: Status | G3: Assigned to | H3: Editor notes | I3: Magazine angle | J3: Source | K3: Digest date | L3: Original headline | M3: Summary | N3: Google News edition | O3: Published | P3: Issue window | Q3: Keywords | R3: Keyword score | S3: Article URL | T3: In Dashboard selection | U3: Top-10 key (helper)
A4: 1 | B4: Automatic segmentation of rock mass fracture networks from UAV imagery using cross-domain transfer learning under scarce labels. | C4: Digital Geotechnics | D4: 5 | E4: Academia-to-Industry topic | F4: To review | I4: Can transfer learning from related image domains reliably segment rock fracture networks in UAV imagery when labelled data are scarce, and how accurate are the results? | J4: 生物通 | K4: 46319 | L4: 标签稀缺条件下基于跨域迁移学习的无人机岩体裂隙网络自动分割方法 | N4: China | O4: 46318 | P4: 2026-Q4 | R4: 0 | S4: https://news.google.com/rss/articles/CBMibkFVX3lxTE8wdVhYVXYyQ3RwMHAtOTNnUkh5TnhCcEtVem9XenhDMFo2UVFHbWtIaGIzVHhLb1BFQmd2akRLZkFMd1pQNWJDRElESUY1SUdvLWFfd1ZaUW5tZ0ZFcmIxckZxbXg1Z1RrbXI5V0Zn?oc=5 | T4: =IF($B4="",0,IF(AND(OR(OR(Dashboard!$B$5="All themes",Dashboard!$B$5=""),$C4=Dashboard!$B$5),OR(OR(Dashboard!$G$5="All uses",Dashboard!$G$5=""),$E4=Dashboard!$G$5),N($D4)>=Lists!$H$2,OR(OR(Dashboard!$N$5="All windows",Dashboard!$N$5=""),$P4=Dashboard!$N$5)),1,0)) | U4: =IF($T4=1,N($D4)*1E14+MIN(MAX(N($R4),0),9999)*1E10+MIN(N($K4),99999)*1E5+99999-MIN(ROW(),99999),"")
A5: 2 | B5: Landslide-prevention embankment threatens residential area | C5: Hazards & Resilience | D5: 4 | E5: Feature lead | F5: To review | I5: Can retaining and protective embankments be designed to resist landslide loading from upslope slopes beside settlements, and how should such risk be assessed? | J5: Vietnam.vn | K5: 46319 | L5: Tanggul pencegah tanah longsor 'mengancam' kawasan permukiman. | N5: Indonesia | O5: 46318 | P5: 2026-Q4 | Q5: landslide, embankment | R5: 13 | S5: https://news.google.com/rss/articles/CBMia0FVX3lxTE45UVhrbTdIV2NXaVloOTBleGdWeThGbHNoSTJtMTE3cFlfalpoYVBnUEFoUVRJQUp5Z2pVOEZvaGZzRUtjRWtOMzY3Wll0RHJOUTB6c0JYdGEzOXk2VXltZUFkc3RURDBUYUg4?oc=5 | T5: =IF($B5="",0,IF(AND(OR(OR(Dashboard!$B$5="All themes",Dashboard!$B$5=""),$C5=Dashboard!$B$5),OR(OR(Dashboard!$G$5="All uses",Dashboard!$G$5=""),$E5=Dashboard!$G$5),N($D5)>=Lists!$H$2,OR(OR(Dashboard!$N$5="All windows",Dashboard!$N$5=""),$P5=Dashboard!$N$5)),1,0)) | U5: =IF($T5=1,N($D5)*1E14+MIN(MAX(N($R5),0),9999)*1E10+MIN(N($K5),99999)*1E5+99999-MIN(ROW(),99999),"")
A6: 3 | B6: Storms in Liguria, major landslide in Savona: the collapse destroyed a city road | C6: Hazards & Resilience | D6: 4 | E6: News brief | F6: To review | I6: What triggered this large rock or soil slope failure in Savona during heavy rain, and what does the collapse reveal about slope stability in Liguria? | J6: agenzia giornalistica opinione | K6: 46319 | L6: RAINEWS * CRONACA: «MALTEMPO IN LIGURIA, GRANDE FRANA A SAVONA: IL CROLLO HA DISTRUTTO UNA STRADA CITTADINA | N6: Italy | O6: 46317 | P6: 2026-Q4 | Q6: landslide, collapse | R6: 11 | S6: https://news.google.com/rss/articles/CBMi7gFBVV95cUxQTGNab2ZBb3hvUXZRVXBCeDFRX2NqU0ZfeVdFZXgtbm5WZDl4aFd0eUdSYXdjNmotcS1ReUZhM1BBc2hITEpkQlpBTmlabzRycmN1ZkQwLVlDa3NzZWJuZXhnNC1jRXlkV1EybVFoQld3VlRaZ241ZkVMazRlZHB1NWplMjVpaWJtMHA3SHBZaEhhMHU0RE01Mk0taFU1OTBaTmg0U1lFYnI5cjhwaEZPUmd2ZTdTVHpxVjBfNk9mRFREOXNWNXJTM29OTnY3NHd0dGJYNVJoaHc4LWQxaUVOajhsaTdWU3dFbVd0ZUt3?oc=5 | T6: =IF($B6="",0,IF(AND(OR(OR(Dashboard!$B$5="All themes",Dashboard!$B$5=""),$C6=Dashboard!$B$5),OR(OR(Dashboard!$G$5="All uses",Dashboard!$G$5=""),$E6=Dashboard!$G$5),N($D6)>=Lists!$H$2,OR(OR(Dashboard!$N$5="All windows",Dashboard!$N$5=""),$P6=Dashboard!$N$5)),1,0)) | U6: =IF($T6=1,N($D6)*1E14+MIN(MAX(N($R6),0),9999)*1E10+MIN(N($K6),99999)*1E5+99999-MIN(ROW(),99999),"")
A7: 4 | B7: At Khanh Le pass, traffic will be interrupted at 30-minute intervals to deal with landslides; road users should plan accordingly | C7: Hazards & Resilience | D7: 4 | E7: Feature lead | F7: To review | I7: How should traffic management and monitoring be combined with slope stabilisation on mountain passes subject to recurrent landslides? | J7: Vietnam.vn | K7: 46319 | L7: En el paso de Khanh Le, el tráfico se interrumpirá a intervalos de 30 minutos para hacer frente a los deslizamientos de tierra; los usuarios de la carretera deben tenerlo en cuenta. | N7: Spain | O7: 46319 | P7: 2026-Q4 | Q7: landslide | R7: 10 | S7: https://news.google.com/rss/articles/CBMiogFBVV95cUxQNGhpZmtjSDF5eDFZZEJXaTdIZWo2QVZTRDVlc3E0T2pvQ2tRaURBcHpRUk5hSmFDNjNuaGV5X1pHeVdqc2RjR1dOQVhPc2tUUVRmb2RiWnB0dWNDcU96QUxGcVg1dmNxRlpfdTNmT0Z5ZG4wSXNTSmR5OUY4ZmRZcW9kNmRHS0ZaVUxyMW9ySU5TSWJlNzJCWWJaZGlrRHd1a2c?oc=5 | T7: =IF($B7="",0,IF(AND(OR(OR(Dashboard!$B$5="All themes",Dashboard!$B$5=""),$C7=Dashboard!$B$5),OR(OR(Dashboard!$G$5="All uses",Dashboard!$G$5=""),$E7=Dashboard!$G$5),N($D7)>=Lists!$H$2,OR(OR(Dashboard!$N$5="All windows",Dashboard!$N$5=""),$P7=Dashboard!$N$5)),1,0)) | U7: =IF($T7=1,N($D7)*1E14+MIN(MAX(N($R7),0),9999)*1E10+MIN(N($K7),99999)*1E5+99999-MIN(ROW(),99999),"")
A8: 5 | B8: Valmontone, bad weather: tuff slope collapses onto Prenestina road, road partially closed | C8: Hazards & Resilience | D8: 4 | E8: News brief | F8: To review | I8: What causes tuff cliff collapse in volcanic deposits under rainfall, and how can such slopes be assessed and stabilised near roads? | J8: Il Giornale dei Castelli Romani | K8: 46319 | L8: Valmontone, maltempo: frana costone di tufo sulla via Prenestina, strada parzialmente chiusa | N8: Italy | O8: 46319 | P8: 2026-Q4 | Q8: landslide | R8: 10 | S8: https://news.google.com/rss/articles/CBMizAFBVV95cUxOX19SY3ozdEtSRFpyZlE3a3o4LWtuMTdJeXVsZkVtZVJIaXJzbndtWVd2T21uQncydzJ1bmZONW1yVU9DVExhUFI5VmI3RkVHbjJqTjZWSXpjd1NLeDViOHZnLWo5ZV9oYVRNZi1KN3E3OERXVC1pdzlDVlBvY3pHZE1WRm9vR0E5VnNNdXN3SU9xbFVGRzY4UkstZUpkYTlMYjJobWoxTDRDNWVqYWdlR2taRV94RG9yaFJuUExrN1VCT2ZpTkFNQllycXo?oc=5 | T8: =IF($B8="",0,IF(AND(OR(OR(Dashboard!$B$5="All themes",Dashboard!$B$5=""),$C8=Dashboard!$B$5),OR(OR(Dashboard!$G$5="All uses",Dashboard!$G$5=""),$E8=Dashboard!$G$5),N($D8)>=Lists!$H$2,OR(OR(Dashboard!$N$5="All windows",Dashboard!$N$5=""),$P8=Dashboard!$N$5)),1,0)) | U8: =IF($T8=1,N($D8)*1E14+MIN(MAX(N($R8),0),9999)*1E10+MIN(N($K8),99999)*1E5+99999-MIN(ROW(),99999),"")
A9: 6 | B9: Bonea, landslide in Capo locality: mayor closes three roads by urgent order | C9: Hazards & Resilience | D9: 4 | E9: News brief | F9: To review | I9: What ground investigation would confirm the landslide mechanism at Capo locality and guide safe reopening of the three closed roads? | J9: Tv7 Benevento | K9: 46319 | L9: BONEA, FRANA IN LOCALITÀ CAPO: IL SINDACO CHIUDE TRE STRADE CON ORDINANZA URGENTE | N9: Italy | O9: 46319 | P9: 2026-Q4 | Q9: landslide | R9: 10 | S9: https://news.google.com/rss/articles/CBMipwFBVV95cUxQM0JfTHl5bmwxRmJ6Y3lLZ2l6XzB1c0lkclVfRzJ2clZEV29YU25kOWNsX1hXNjFuUnJnVGNjRXBFa0V2RWlYVllQOVEzV1ZCY3VYNENpdk9wSGVNNlUtNGVwdGZhZDY5UUVTYW1OZHQ1TkFoUURUTFMwSWdoLU90QTU2VE5Md1NKOU1Rd041aXFxNUJ1OGc3QTAxLUpGbndSWXh0czMzSQ?oc=5 | T9: =IF($B9="",0,IF(AND(OR(OR(Dashboard!$B$5="All themes",Dashboard!$B$5=""),$C9=Dashboard!$B$5),OR(OR(Dashboard!$G$5="All uses",Dashboard!$G$5=""),$E9=Dashboard!$G$5),N($D9)>=Lists!$H$2,OR(OR(Dashboard!$N$5="All windows",Dashboard!$N$5=""),$P9=Dashboard!$N$5)),1,0)) | U9: =IF($T9=1,N($D9)*1E14+MIN(MAX(N($R9),0),9999)*1E10+MIN(N($K9),99999)*1E5+99999-MIN(ROW(),99999),"")
A10: 7 | B10: La frana del Cencione Tra fango e polemiche Le ruspe sono al lavoro | C10: Hazards & Resilience | D10: 4 | E10: Feature lead | F10: To review | I10: How should authorities balance urgent earthworks with geotechnical investigation and accountability when a landslide site becomes politically contested? | J10: Zazoom Social News | K10: 46319 | N10: Italy | O10: 46318 | P10: 2026-Q4 | Q10: landslide | R10: 10 | S10: https://news.google.com/rss/articles/CBMirwFBVV95cUxPRkxsbl9ZdlM1cmloa1JxT3ZENFdkYUI5U3pIZy1UM005NU9SVVFIVjVmZ1ZvTDNybGJkMHAtc3Ewd3RldnRYWHlrSnQ2R1hXN2xpR1BNREFxTlRlb2tFMnFJZ01VSEZqN0ZheUtlbWJEd3h2SURJb3ppVWl6dTU2Y21zZGJGR1hpMWdNUmNfdWluZDJQYzZkeC1QTHhEUFNmcVhTVWtnWWxiUDczMmtr?oc=5 | T10: =IF($B10="",0,IF(AND(OR(OR(Dashboard!$B$5="All themes",Dashboard!$B$5=""),$C10=Dashboard!$B$5),OR(OR(Dashboard!$G$5="All uses",Dashboard!$G$5=""),$E10=Dashboard!$G$5),N($D10)>=Lists!$H$2,OR(OR(Dashboard!$N$5="All windows",Dashboard!$N$5=""),$P10=Dashboard!$N$5)),1,0)) | U10: =IF($T10=1,N($D10)*1E14+MIN(MAX(N($R10),0),9999)*1E10+MIN(N($K10),99999)*1E5+99999-MIN(ROW(),99999),"")
A11: 8 | B11: TNI helps landslide victims in Lae Ikan, Subulussalam | C11: Hazards & Resilience | D11: 4 | E11: News brief | F11: To review | I11: What role can emergency response and rapid geotechnical assessment play after a landslide in a mountainous Indonesian village? | J11: RRI.co.id | K11: 46319 | L11: TNI Bantu Korban Longsor di Lae Ikan Subulussalam | N11: Indonesia | O11: 46319 | P11: 2026-Q4 | Q11: landslide | R11: 10 | S11: https://news.google.com/rss/articles/CBMiogFBVV95cUxOYkthemxCdGdtc1c3TnBBbGY4MVZlMDFvWnZiX3E4UERSQ1lsX2g4R0x5VHVaVndQdnJHQTBZSy02bV8wT1d4RVZ6WHRVN2w0UUx1MFRMbDhINzgtWlJJLXFKOHIzWFRZa1VmZUVFNUNCM3hRdE9GUGZpdVNQQnd3ZmxRTWZFOGU5REFvOTg4cG40YkU1bDhlZ2pQSkR5Ti04Q1E?oc=5 | T11: =IF($B11="",0,IF(AND(OR(OR(Dashboard!$B$5="All themes",Dashboard!$B$5=""),$C11=Dashboard!$B$5),OR(OR(Dashboard!$G$5="All uses",Dashboard!$G$5=""),$E11=Dashboard!$G$5),N($D11)>=Lists!$H$2,OR(OR(Dashboard!$N$5="All windows",Dashboard!$N$5=""),$P11=Dashboard!$N$5)),1,0)) | U11: =IF($T11=1,N($D11)*1E14+MIN(MAX(N($R11),0),9999)*1E10+MIN(N($K11),99999)*1E5+99999-MIN(ROW(),99999),"")
A12: 9 | B12: Source: no casualties in Tanta building collapse and 4 cars destroyed - video and photos | C12: Hazards & Resilience | D12: 4 | E12: News brief | F12: To review | I12: What caused the collapse of this Tanta building, and what foundation or excavation failure lessons does it offer? | J12: Masrawy | K12: 46319 | L12: مصدر: لاضحايا في انهيار عقار طنطا وتحطم 4 سيارات - فيديو وصور | N12: Egypt | O12: 46319 | P12: 2026-Q4 | Q12: collapse | R12: 7 | S12: https://news.google.com/rss/articles/CBMitANBVV95cUxNUUlBdHRnYnNzb3ZOX1BlZ1VIbWl3ZzdvbEhqenMtbHpwbVd5VHoyTTdwWklBOUFGMWxtd1RLY2tMcnZ4TWZWSUVXZHJYOFVKV3dxcjcwSFJqeUtTbS0tMm1FSFpmWk16WkhMOGU4OGRyZ0kwY0Z4cl9PZ2s3blFCZHljWXdXVzJtUmprT2VmWDY2U2dndVpfcEJmTDc0SXlhd0hyLWU0VE1VeVMtalJ4cUFGTU1CdnhoYW5KeXE4bEh4R2prb1dmWHdpNmZJMm1TMk4zWmJxM1BUUFdXNHZYSDczTFk4cjZOTll3Si1kNVB6MzdqNkd6VEdSeUM0aDJHY05HRW9QR0htUS1pdHRTdmFnZC1kcV84eklxcHlZeTVJd3A4NEpvTU9DT19IQXVZUVhhTEE2OFIwMGttaEIxODJ0ZWhQR1UwcGVLNVg1TlVDaHUzaU5ZTmhsMkdTeGFORm9Hd3hDUlNESy1maG5ZY2g3T0NFOVgwRGxoTXJ4d2FEV3p6bm83cllHTV9QLW90VW14WlZOWkJvblJ2S0E4VlBrbUhLaVRJbnY3R1AzVzFDN2xy0gGEBEFVX3lxTFBBQTVYY2h4THQwaTRndVVTeE55dFdQd3Z6MG5PMzJOU3FSakNBM25YYzhQZGtfRkx5bnNzUWRRZFN5UkJqR2xaNXQ5RjFXWWtnMlAwdTBZVS1oTmxuWmt5TnRTX0YxbHVVWTlEMHNrRUNkNVNzejk1SGdOVm9rTjRUTXZuY0VsX1lzZENuXzB6UmRPOEczTHg4NmJfYUQzUTJVNXJTem1BWU1KUFZmMnl6eUVKT09HN05CcjBUQmFrOVRpZjNnLWU0WGM1Qll1a2pqdWx4VUVSaUdfMjJlNEh4dlgwMWZ2YXY0RW52ZE9WZWRKS1kwYXhyeTYydV9CQVRtVGhpeUtsTlVTeHAxSngtb0NhMVR3bkhKLVlVZ3N3VUk1QU1SWFFYcWdWNkJwcGg1bFBoVm5KYmc5NEdQX3I5QWM3OW9HbF85czRBUXd6eXpaTWpnZkY0RDBIVzVTbnV4QUItNXdNaW1DZXpDQTNtNG9Od3BveDNTMnB2RmpEN1ZQb2NUNmN1cC1mSW1sWWs1NEswWU5mUWV3LWI3a3hBRTVuYkJaaDdObDczd0ZfWUw1SXRRVXM4ZWs2bm9lNk5hYWNkU3F2bktWNUl1bXByUTRzMGVOa2VwdzVibE9Za2xvQmJqRUY0T09va2NmczZTTlZfMlN6eFZMN1owYUpVOFZrSw?oc=5 | T12: =IF($B12="",0,IF(AND(OR(OR(Dashboard!$B$5="All themes",Dashboard!$B$5=""),$C12=Dashboard!$B$5),OR(OR(Dashboard!$G$5="All uses",Dashboard!$G$5=""),$E12=Dashboard!$G$5),N($D12)>=Lists!$H$2,OR(OR(Dashboard!$N$5="All windows",Dashboard!$N$5=""),$P12=Dashboard!$N$5)),1,0)) | U12: =IF($T12=1,N($D12)*1E14+MIN(MAX(N($R12),0),9999)*1E10+MIN(N($K12),99999)*1E5+99999-MIN(ROW(),99999),"")
A13: 10 | B13: 25 subdistricts in Bandung Regency classified as medium-high landslide potential | C13: Hazards & Resilience | D13: 4 | E13: Regional insight | F13: To review | I13: How are landslide susceptibility maps produced for districts, and how should medium-high hazard classes inform land-use planning? | J13: Pikiran-Rakyat.com | K13: 46319 | L13: 25 Kecamatan di Kabupaten Bandung Masuk Kategori Potensi Gerakan Tanah Menengah-Tinggi | N13: Indonesia | O13: 46319 | P13: 2026-Q4 | R13: 6 | S13: https://news.google.com/rss/articles/CBMi0gFBVV95cUxOVW5ENnJ6RnYwS3VyQ3dPQW9qS0NBcjZxeGNNcHBlVWttczllOUhhLVNuT2ljMkN3NFZodHJISlRZUG1GTTNaTVN6SF90ZE1kMl9teDFSWmsza2hpR1BLM3ZtbkV2cWg2NWk2TW9ac0JRNnl5WEFlWS1NWG5UNEVXMlVzNEdNaThBRVgtSlJVc0x5WDBHbmFqTW1LUFJTN3hDZXZIU3VKeFM4VV9faHd2cU1zUXFFdHJOaWhGdnZiel91TjBRMFFoc2FwSFZPMUJjbGfSAdcBQVVfeXFMT3BsOGJPRzNGNTBnZFJNbWVldVNXaGtQRG5oRlZEaHAzTUt2cml2TXRHdDUyWE5MMEdSdXdhdS05NWJlSXRhV3NXamRkcFk0WXR1TmxkNFNIWFlqUGRMWTY1Wm52QmUtU0lsVlF1aUt3NUtJNHJsRW9GSzNtTXN4d1BhdGQyWGh3WUVoWGJKYkhXejlCM2NQRWZkbFFmQ3EtSlZLYWI1dG45OXA1R3E5c0dtNTZBTVZVNjZLRDAwUEJQT3dpTDl5SDJObTYxbFBETVFFb1c4Z0E?oc=5 | T13: =IF($B13="",0,IF(AND(OR(OR(Dashboard!$B$5="All themes",Dashboard!$B$5=""),$C13=Dashboard!$B$5),OR(OR(Dashboard!$G$5="All uses",Dashboard!$G$5=""),$E13=Dashboard!$G$5),N($D13)>=Lists!$H$2,OR(OR(Dashboard!$N$5="All windows",Dashboard!$N$5=""),$P13=Dashboard!$N$5)),1,0)) | U13: =IF($T13=1,N($D13)*1E14+MIN(MAX(N($R13),0),9999)*1E10+MIN(N($K13),99999)*1E5+99999-MIN(ROW(),99999),"")
A14: 11 | B14: Gochang-Buan Noeuldaegyo Enters Geotechnical Survey Phase; Construction Targeted for January 2028 | C14: Infrastructure & the Underground City | D14: 4 | E14: News brief | F14: To review | I14: What ground conditions will the geotechnical survey reveal for this Korean nuclear-related or major construction project, and how will they shape the 2028 schedule? | J14: 아시아경제 | K14: 46319 | N14: United Kingdom | O14: 46317 | P14: 2026-Q4 | Q14: geotechnical | R14: 5 | S14: https://news.google.com/rss/articles/CBMibEFVX3lxTE9qd0p2T2p3a1lzbEg5TnFXNDZ2VXRhLWIzbGk1U0pnQlFCUk1RU2tqdFFXeEt4RkM3bThuVUUyelBfNHJMdlFmMThyZG9UakhLLTFqTGJBTDBKVmN1bXlqQmYyX1U3eHIyWTNfTw?oc=5 | T14: =IF($B14="",0,IF(AND(OR(OR(Dashboard!$B$5="All themes",Dashboard!$B$5=""),$C14=Dashboard!$B$5),OR(OR(Dashboard!$G$5="All uses",Dashboard!$G$5=""),$E14=Dashboard!$G$5),N($D14)>=Lists!$H$2,OR(OR(Dashboard!$N$5="All windows",Dashboard!$N$5=""),$P14=Dashboard!$N$5)),1,0)) | U14: =IF($T14=1,N($D14)*1E14+MIN(MAX(N($R14),0),9999)*1E10+MIN(N($K14),99999)*1E5+99999-MIN(ROW(),99999),"")
A15: 12 | B15: Primeval forest grows at bottom of 120-meter-deep sinkhole in central Vietnam | C15: Characterisation & Modelling | D15: 4 | E15: Feature lead | F15: To review | I15: How do karst collapse sinkholes form in limestone terrain, and what do such deep features reveal about cave ground stability and hazard mapping? | J15: VnExpress International | K15: 46319 | N15: United Kingdom | O15: 46319 | P15: 2026-Q4 | Q15: sinkhole | R15: 4 | S15: https://news.google.com/rss/articles/CBMizAFBVV95cUxNd2dFendqYTRDcVVfLTVONjFFenlXV3pwTHVkVEJhb2ZfYzdKbF9XTDgxVXJqY1d4QWo3bi1CR250aUV6Y2FmQTktNUtTbU1FRnA2WUVzdFRiU2lRa3M1VzdwRUxzbWF0eUJmMER5Y2Yxb1V2aVdta0M4OGpjWmV6VGFnUVFLNjlQand3S3hSaTBFTUJZQ0JfNVBvZmF6NVpLSkdEMVlBLWt5VW5wYlhSOHBrdHVjU1FVMm41cW4tN0MwbTZ2Z2dULUZJemk?oc=5 | T15: =IF($B15="",0,IF(AND(OR(OR(Dashboard!$B$5="All themes",Dashboard!$B$5=""),$C15=Dashboard!$B$5),OR(OR(Dashboard!$G$5="All uses",Dashboard!$G$5=""),$E15=Dashboard!$G$5),N($D15)>=Lists!$H$2,OR(OR(Dashboard!$N$5="All windows",Dashboard!$N$5=""),$P15=Dashboard!$N$5)),1,0)) | U15: =IF($T15=1,N($D15)*1E14+MIN(MAX(N($R15),0),9999)*1E10+MIN(N($K15),99999)*1E5+99999-MIN(ROW(),99999),"")
A16: 13 | B16: More than 300 neighbourhoods at risk from rains; sinkhole on Eloy Alfaro casts doubt on Quito's underground infrastructure | C16: Infrastructure & the Underground City | D16: 4 | E16: Feature lead | F16: To review | I16: How can cities detect and prevent sinkholes caused by leaking pipes and eroded soils in urban ground, and what does Quito's case reveal about underground infrastructure monitoring? | J16: El Universo | K16: 46319 | L16: Más de 300 barrios en riesgo por las lluvias, socavón en la Eloy Alfaro pone en duda la infraestructura subterránea de Quito | N16: Mexico | O16: 46318 | P16: 2026-Q4 | Q16: sinkhole | R16: 4 | S16: https://news.google.com/rss/articles/CBMi_AJBVV95cUxQQ3p2THhYWmNjejMwUW5mdmI0RzhkWWxJQ2F6aEIxd0pCLUNsSExLWDB3MHBlMGMwT1l2MlpfYWEzQmZxbHkyc0Mwc2xkLWJMMGRuZ2NkeEtmNlpJUF9YZllSZU42elZTRG5wYzhrSUo2NWxZV3J3UEkwbWZ2bmVEczJTeWFNbzhqbnZ5UlMyM3NnZ25MalJwY3Q2UDRCR0FXWFNXcTRaWURzXzZhcTVjWW85SERYeE1RelFwdF9sa1dkUVF5dldKcTVncy1VZzZhc19PQlYtbU5KRFphYmt1a2JFT0lFTURCNTBxM1J6bWhsY2hwdjJXaktBWGVsYkFkMzVEbHZSQ0lVRjRVX2NHVUFlS0Y4SzU5V05DNWRlTWxhVThGSnFKQ2l1SnJ5LXRCZmJfTHBJSzZTQUV3QkVyRjVISUpkSm0weHBSSUo3RjB6QUJOSkUtdG5mMGZQWlhzekZZVC0wb25qOHA5eVQ3b3lCWU5oT21rN1JsR9IB_AJBVV95cUxQQ3p2THhYWmNjejMwUW5mdmI0RzhkWWxJQ2F6aEIxd0pCLUNsSExLWDB3MHBlMGMwT1l2MlpfYWEzQmZxbHkyc0Mwc2xkLWJMMGRuZ2NkeEtmNlpJUF9YZllSZU42elZTRG5wYzhrSUo2NWxZV3J3UEkwbWZ2bmVEczJTeWFNbzhqbnZ5UlMyM3NnZ25MalJwY3Q2UDRCR0FXWFNXcTRaWURzXzZhcTVjWW85SERYeE1RelFwdF9sa1dkUVF5dldKcTVncy1VZzZhc19PQlYtbU5KRFphYmt1a2JFT0lFTURCNTBxM1J6bWhsY2hwdjJXaktBWGVsYkFkMzVEbHZSQ0lVRjRVX2NHVUFlS0Y4SzU5V05DNWRlTWxhVThGSnFKQ2l1SnJ5LXRCZmJfTHBJSzZTQUV3QkVyRjVISUpkSm0weHBSSUo3RjB6QUJOSkUtdG5mMGZQWlhzekZZVC0wb25qOHA5eVQ3b3lCWU5oT21rN1JsRw?oc=5 | T16: =IF($B16="",0,IF(AND(OR(OR(Dashboard!$B$5="All themes",Dashboard!$B$5=""),$C16=Dashboard!$B$5),OR(OR(Dashboard!$G$5="All uses",Dashboard!$G$5=""),$E16=Dashboard!$G$5),N($D16)>=Lists!$H$2,OR(OR(Dashboard!$N$5="All windows",Dashboard!$N$5=""),$P16=Dashboard!$N$5)),1,0)) | U16: =IF($T16=1,N($D16)*1E14+MIN(MAX(N($R16),0),9999)*1E10+MIN(N($K16),99999)*1E5+99999-MIN(ROW(),99999),"")
A17: 14 | B17: Giant sinkhole discovered in Phong Nha-Ke Bang National Park | C17: Characterisation & Modelling | D17: 4 | E17: Feature lead | F17: To review | I17: How are giant karst sinkholes detected and characterised in limestone terrain, and what hazards do they pose to park access and infrastructure? | J17: Baolangson.vn | K17: 46319 | L17: Giant sinkhole discovered in Phong Nha-Ke Bang National Park | N17: United Kingdom | O17: 46319 | P17: 2026-Q4 | Q17: sinkhole | R17: 4 | S17: https://news.google.com/rss/articles/CBMinwFBVV95cUxQbmljanByeFhpYlNScnE2RHN0UUVIMy1oenIwbzdmbFBTeHUxMXZjT2xhY3dnbm5UdW42ZTNhTk5LMWNWTlg0eFBvTnE2Q1ZqY2JlNElKTVdqd0x1M0liaTlFRzVBUkFiUXdfY29PUUJsU2M3TEVaVHpkeUtiSkdqV0lPN3Y1dV9ZR1B5bk5OalNJNGZPMVlRZUd5RHJtOUU?oc=5 | T17: =IF($B17="",0,IF(AND(OR(OR(Dashboard!$B$5="All themes",Dashboard!$B$5=""),$C17=Dashboard!$B$5),OR(OR(Dashboard!$G$5="All uses",Dashboard!$G$5=""),$E17=Dashboard!$G$5),N($D17)>=Lists!$H$2,OR(OR(Dashboard!$N$5="All windows",Dashboard!$N$5=""),$P17=Dashboard!$N$5)),1,0)) | U17: =IF($T17=1,N($D17)*1E14+MIN(MAX(N($R17),0),9999)*1E10+MIN(N($K17),99999)*1E5+99999-MIN(ROW(),99999),"")
A18: 15 | B18: Special feature: Typhoon No. 25 triggers many landslides; dangers hidden in Chiba's Boso Peninsula terrain, 'high valley density'. | C18: Hazards & Resilience | D18: 4 | E18: Feature lead | F18: To review | I18: Why does high valley density amplify landslide susceptibility in the Boso Peninsula, and how do weathered sedimentary slopes respond to intense typhoon rainfall? | J18: Yahoo!ニュース | K18: 46319 | L18: 【特集】台風25号で土砂崩れ多発 千葉・房総半島の地形に潜む危険 「谷密度が高い」（チバテレ） | N18: Japan | O18: 46318 | P18: 2026-Q4 | Q18: landslide | R18: 4 | S18: https://news.google.com/rss/articles/CBMif0FVX3lxTE9paXItcTdLR3g0R0hhZGZwQVFjNHJEOWJJRF84Rzdfa0tRQ0taaTVxd19rWFBLOHNuUkU2N081UDJIWVZNQ09NUDJBQ0p2V0FwS1lNV213UnNvV0xvcU1zTUpWWG1iTnFMclFRVjh4SUNoREdra2loMWh0ZGVIN0E?oc=5 | T18: =IF($B18="",0,IF(AND(OR(OR(Dashboard!$B$5="All themes",Dashboard!$B$5=""),$C18=Dashboard!$B$5),OR(OR(Dashboard!$G$5="All uses",Dashboard!$G$5=""),$E18=Dashboard!$G$5),N($D18)>=Lists!$H$2,OR(OR(Dashboard!$N$5="All windows",Dashboard!$N$5=""),$P18=Dashboard!$N$5)),1,0)) | U18: =IF($T18=1,N($D18)*1E14+MIN(MAX(N($R18),0),9999)*1E10+MIN(N($K18),99999)*1E5+99999-MIN(ROW(),99999),"")
A19: 16 | B19: M4 to be shut and speed limits put in place after landslide | C19: Hazards & Resilience | D19: 4 | E19: News brief | F19: To review | I19: What likely caused the M4 landslide, and how should highway embankments and cuttings be assessed for failure after heavy rainfall? | J19: South West Farmer | K19: 46319 | N19: United Kingdom | O19: 46317 | P19: 2026-Q4 | Q19: landslide | R19: 4 | S19: https://news.google.com/rss/articles/CBMikwFBVV95cUxOYkdTUURQN0hOX2VUcUZ1Rk5ZS1R4alNNVkRLOFJoMHpqUlFxLS1HQ3U5clQtcG9UeWNmd3dYRHFNYnJmSjBHR25QWlZjRUM0Z0RVWnMwbUdsTmZKRE5iZ3NzNGgxbkY5cnFzam9Ub05aYlRKb292ODJEX284ZmdsLXFIVzNZcTdIakNIVjJUR1ZvMEE?oc=5 | T19: =IF($B19="",0,IF(AND(OR(OR(Dashboard!$B$5="All themes",Dashboard!$B$5=""),$C19=Dashboard!$B$5),OR(OR(Dashboard!$G$5="All uses",Dashboard!$G$5=""),$E19=Dashboard!$G$5),N($D19)>=Lists!$H$2,OR(OR(Dashboard!$N$5="All windows",Dashboard!$N$5=""),$P19=Dashboard!$N$5)),1,0)) | U19: =IF($T19=1,N($D19)*1E14+MIN(MAX(N($R19),0),9999)*1E10+MIN(N($K19),99999)*1E5+99999-MIN(ROW(),99999),"")
A20: 17 | B20: Nilgiris Landslides: bus driver killed, Schoolchildren among 300 rescued | C20: Hazards & Resilience | D20: 4 | E20: News brief | F20: To review | I20: What triggered the Nilgiris landslides, and what early-warning and slope-stability measures could reduce fatalities on hill-region roads? | J20: The Hindu | K20: 46319 | N20: United Kingdom | O20: 46319 | P20: 2026-Q4 | Q20: landslide | R20: 4 | S20: https://news.google.com/rss/articles/CBMivwFBVV95cUxOdTlOSzlWSmNZWUlrbUJCNEsxMzNVOFd2NWFGRThtXzZjRHR1V2gxZDFvREd5ckoyQ0NZVzdYWldycGN2SUhDYVZfRHF0UjdWaU9wdUZRbTJMdVhWektCZl9HTHMxdF9rcTdTSk1PMnhJcmFGZ0t1SFFlZzlFdVFXejVkZ3ppbnN5cEJtMldLUjZNOTRHVUtzUW1jb3pTWmtLa0dNS1daaXBRRnRKajlObjZtUGVzSlAwTkhId0Y3RdIBxgFBVV95cUxNYXR2aFZPcUlLdkRSRE9pLU1TdW9IbTFXZklLRVBjTWJjMURUTFNCVERtSXdrLUNnRnBBNXJpNEFiQ3l3bFZfNm96d3N3TW56eUVscDZ1S2NTdmFqWWdxN0ZxSVBwSUk1OFI5TEx4MjB5ZWVfQnNvZ1FWbDFZa3lDck5FVW9nZ1QtZ2RTTGtNZ21pUWxyYjd3c3RUVnhwRUhncnp3cGhMaS02RzBNeUJtQWtaWng4UUQ0cG1pbkFGclZEMW5IU1E?oc=5 | T20: =IF($B20="",0,IF(AND(OR(OR(Dashboard!$B$5="All themes",Dashboard!$B$5=""),$C20=Dashboard!$B$5),OR(OR(Dashboard!$G$5="All uses",Dashboard!$G$5=""),$E20=Dashboard!$G$5),N($D20)>=Lists!$H$2,OR(OR(Dashboard!$N$5="All windows",Dashboard!$N$5=""),$P20=Dashboard!$N$5)),1,0)) | U20: =IF($T20=1,N($D20)*1E14+MIN(MAX(N($R20),0),9999)*1E10+MIN(N($K20),99999)*1E5+99999-MIN(ROW(),99999),"")
A21: 18 | B21: Tamil Nadu landslide kills government bus driver after 50 passengers evacuated near Parliyar | C21: Hazards & Resilience | D21: 4 | E21: News brief | F21: To review | I21: What ground and rainfall conditions caused the Parliyar landslide that hit a bus, and how can hill-road slopes be screened for similar risk? | J21: Telangana Today | K21: 46319 | N21: United States | O21: 46319 | P21: 2026-Q4 | Q21: landslide | R21: 4 | S21: https://news.google.com/rss/articles/CBMiuwFBVV95cUxQbU93M0hrSW4zTW1qTEQtSGtzZmRYcEJVMlc1UDQ1ZVRrRGhCYXcxaEpuTFNRLXZHdlozOXFvUzJzdzBWNVZFQW1xdXpOcThIVGN3T204N1JrOTcxOGQyT1VRRHBPSlZsWUREOXZXbTRJV29wWmtZUFhlZFFtWkRhRHRnYmRnMDQ2RTJ5VDVWUG9DaW04b0xoOGxhQTVnV2kwVkQyckVuYlVsaGdNenM0OHdGN2N6Tkw2azRR?oc=5 | T21: =IF($B21="",0,IF(AND(OR(OR(Dashboard!$B$5="All themes",Dashboard!$B$5=""),$C21=Dashboard!$B$5),OR(OR(Dashboard!$G$5="All uses",Dashboard!$G$5=""),$E21=Dashboard!$G$5),N($D21)>=Lists!$H$2,OR(OR(Dashboard!$N$5="All windows",Dashboard!$N$5=""),$P21=Dashboard!$N$5)),1,0)) | U21: =IF($T21=1,N($D21)*1E14+MIN(MAX(N($R21),0),9999)*1E10+MIN(N($K21),99999)*1E5+99999-MIN(ROW(),99999),"")
A22: 19 | B22: In Massachusetts, sinkhole questions linger as mill demolition clears way for housing units | C22: Hazards & Resilience | D22: 4 | E22: Feature lead | F22: To review | I22: How should sinkhole origin be investigated beneath a former mill site before redevelopment for housing, and what ground remediation is needed? | J22: Yahoo | K22: 46319 | N22: United Kingdom | O22: 46318 | P22: 2026-Q4 | Q22: sinkhole | R22: 4 | S22: https://news.google.com/rss/articles/CBMimwFBVV95cUxOd3VEcWZ4d01oX25TMUhmNDFtX1QtRktKMmhoOWM5Z3BQVGV3TFE5elhLYkhPaWtCUkJTU3paUkRqQjNGdnFYbW1sNWRzRzAyaVFiYlJEWWRaZjY4ckppMTBSTWFlVUpaMHpHLVdMRU11NnFNQUp4Ymtac3UtYk03RndxbVp6V3Exc3p3RFRyTWxyYlkyTDVhcUxWSQ?oc=5 | T22: =IF($B22="",0,IF(AND(OR(OR(Dashboard!$B$5="All themes",Dashboard!$B$5=""),$C22=Dashboard!$B$5),OR(OR(Dashboard!$G$5="All uses",Dashboard!$G$5=""),$E22=Dashboard!$G$5),N($D22)>=Lists!$H$2,OR(OR(Dashboard!$N$5="All windows",Dashboard!$N$5=""),$P22=Dashboard!$N$5)),1,0)) | U22: =IF($T22=1,N($D22)*1E14+MIN(MAX(N($R22),0),9999)*1E10+MIN(N($K22),99999)*1E5+99999-MIN(ROW(),99999),"")
A23: 20 | B23: Magnitude 7 earthquake in Biru County, Nagqu, Tibet; some houses cracked and collapsed. | C23: Hazards & Resilience | D23: 4 | E23: Feature lead | F23: To review | I23: How do high-altitude site conditions and local soils influence seismic damage to rural houses, and what design measures suit such regions? | J23: 新唐人電視台 | K23: 46319 | L23: 西藏那曲市巴青縣7級地震 部分房屋裂縫倒塌 | N23: China | O23: 46318 | P23: 2026-Q4 | Q23: earthquake, collapse | R23: 3 | S23: https://news.google.com/rss/articles/CBMiYEFVX3lxTE9wT0pNRFh5RUpiWk5oQnFGVUlNaGRvbE00QWtoWnQyd2RnWmxDX1JfcTFDRGdZV3R4NV8wM3JnQlhqQlpBdXZOVkQ1SkN1cGpCbEdxQWlyTGVEU3FtOWgzLdIBZkFVX3lxTE43YnlEYmJuNUtFaV9Wblc4S1VBbE5vbFRXSGNlaXhIcjlxYTRtYllySjdLSVUxNk1RTGVmZXRSbXkzUWxsWHR5djNic00yTWw1cVBUQXc2bG9PcUJ3NVlOMGFGQkI0UQ?oc=5 | T23: =IF($B23="",0,IF(AND(OR(OR(Dashboard!$B$5="All themes",Dashboard!$B$5=""),$C23=Dashboard!$B$5),OR(OR(Dashboard!$G$5="All uses",Dashboard!$G$5=""),$E23=Dashboard!$G$5),N($D23)>=Lists!$H$2,OR(OR(Dashboard!$N$5="All windows",Dashboard!$N$5=""),$P23=Dashboard!$N$5)),1,0)) | U23: =IF($T23=1,N($D23)*1E14+MIN(MAX(N($R23),0),9999)*1E10+MIN(N($K23),99999)*1E5+99999-MIN(ROW(),99999),"")
A24: 21 | B24: Giant hole discovered in Phong Nha-Ke Bang National Park. | C24: Characterisation & Modelling | D24: 4 | E24: Feature lead | F24: To review | I24: What geological processes produced this giant hole in karst terrain, and how should such features be investigated and mapped within protected national parks? | J24: Vietnam.vn | K24: 46319 | L24: تم اكتشاف حفرة عملاقة في منتزه فونغ نها-كي بانغ الوطني | N24: Egypt | O24: 46318 | P24: 2026-Q4 | R24: 0 | S24: https://news.google.com/rss/articles/CBMijgFBVV95cUxOUnpVR19vMWtXdWRZRlhOcXE4MTNMakhRWnhFZTVUd3lPYWh6NFJjejFkcS1mbENUSDQtMmdxaVlDNDlLdjBrNktTOEJLR3ZyWXBCbFhjVzk5NVA3b2puWXozVWhYWHlkQXZIYkdkanZYanZ6aVNNSXFiZUR6SnZKcFVGT0ZrbjFLMkt3a3F3?oc=5 | T24: =IF($B24="",0,IF(AND(OR(OR(Dashboard!$B$5="All themes",Dashboard!$B$5=""),$C24=Dashboard!$B$5),OR(OR(Dashboard!$G$5="All uses",Dashboard!$G$5=""),$E24=Dashboard!$G$5),N($D24)>=Lists!$H$2,OR(OR(Dashboard!$N$5="All windows",Dashboard!$N$5=""),$P24=Dashboard!$N$5)),1,0)) | U24: =IF($T24=1,N($D24)*1E14+MIN(MAX(N($R24),0),9999)*1E10+MIN(N($K24),99999)*1E5+99999-MIN(ROW(),99999),"")
A25: 22 | B25: Analytical study of 3D transient dynamic response of a cylindrical cavity in an elastic medium under triangular pulse load. | C25: Characterisation & Modelling | D25: 4 | E25: Academia-to-Industry topic | F25: To review | I25: How do analytical solutions for a cylindrical cavity under triangular pulse loads inform the validation of numerical models for underground openings under impact? | J25: 生物通 | K25: 46319 | L25: 弹性介质中圆柱形空腔受三角形脉冲冲击载荷的三维瞬态动力响应解析研究 | N25: China | O25: 46318 | P25: 2026-Q4 | R25: 0 | S25: https://news.google.com/rss/articles/CBMibkFVX3lxTE5PclBzMHZTYkNxbkRYVWFacWgzMjRTdE1JdmNYSi1xbTlBaVZLRTVjTHpCTlQ4c2lEQ2xoMk9kcEdROGxBOFI4Zk9YV3JGSXdUZDg1blVlelJzbU54VjkzTkUySEV5Z2x2aHY5R0xB?oc=5 | T25: =IF($B25="",0,IF(AND(OR(OR(Dashboard!$B$5="All themes",Dashboard!$B$5=""),$C25=Dashboard!$B$5),OR(OR(Dashboard!$G$5="All uses",Dashboard!$G$5=""),$E25=Dashboard!$G$5),N($D25)>=Lists!$H$2,OR(OR(Dashboard!$N$5="All windows",Dashboard!$N$5=""),$P25=Dashboard!$N$5)),1,0)) | U25: =IF($T25=1,N($D25)*1E14+MIN(MAX(N($R25),0),9999)*1E10+MIN(N($K25),99999)*1E5+99999-MIN(ROW(),99999),"")
A26: 23 | B26: Frana tra via Gentile e via Genova: scatta il senso unico alternato con il semaforo | C26: Hazards & Resilience | D26: 3 | E26: Watch only | F26: To review | I26: Does a landslide on an urban road indicate ground instability requiring geotechnical investigation before reopening? | J26: Savona News | K26: 46319 | N26: Italy | O26: 46319 | P26: 2026-Q4 | Q26: landslide | R26: 10 | S26: https://news.google.com/rss/articles/CBMi7gFBVV95cUxPTThpMkFRUmE3cEhvQ3NuWmhJRnd5UTJ2eFpxUDN1NTJUTmQ0RWhOTlc5M2MyNzVJeUd4TUtzb1BaaUdmdVpRYjN6LXBtdUxubGx4WHVTQ1NQNzU0QVI3N29nNkdWRGdtWTFGYjg2LWU2M0pXY3phYktYM3JVVm9fbjlTdGZRV0I3ZE40eVAxMkJMVlYxRlQzVnpVdFlETlh6a1NKSXNocTU0ZE0zX09tSHhwbXZGa3VZdzJDMTBNMHhoWGwwM2JNbk1BbE94QjhNQW5oY2QwY3RudmhSX2FlcWlxWURMNk04TVNFMU5R0gHuAUFVX3lxTE9NOGkyQVFSYTdwSG9Dc25aaElGd3lRMnZ4WnFQM3U1MlROZDRFaE5OVzkzYzI3NUl5R3hNS3NvUFppR2Z1WlFiM3otcG11TG5sbHhYdVNDU1A3NTRBUjc3b2c2R1ZEZ21ZMUZiODYtZTYzSldjemFiS1gzclVWb19uOVN0ZlFXQjdkTjR5UDEyQkxWVjFGVDNWelV0WUROWHprU0pJc2hxNTRkTTNfT21IeHBtdkZrdVl3MkMxME0weGhYbDAzYk1uTUFsT3hCOE1BbmhjZDBjdG52aFJfYWVxaXFZREw2TThNU0UxTlE?oc=5 | T26: =IF($B26="",0,IF(AND(OR(OR(Dashboard!$B$5="All themes",Dashboard!$B$5=""),$C26=Dashboard!$B$5),OR(OR(Dashboard!$G$5="All uses",Dashboard!$G$5=""),$E26=Dashboard!$G$5),N($D26)>=Lists!$H$2,OR(OR(Dashboard!$N$5="All windows",Dashboard!$N$5=""),$P26=Dashboard!$N$5)),1,0)) | U26: =IF($T26=1,N($D26)*1E14+MIN(MAX(N($R26),0),9999)*1E10+MIN(N($K26),99999)*1E5+99999-MIN(ROW(),99999),"")
A27: 24 | B27: Torrential rain brings hidden hazards: mountain floods and landslides must be strictly prevented; public service advertisement | C27: Hazards & Resilience | D27: 3 | E27: Watch only | F27: To review | I27: How do mountain flood and landslide hazards during intense rainfall get prevented through early warning and slope management? | J27: 凤凰网 | K27: 46319 | L27: 暴雨来袭隐患藏 山洪滑坡需严防｜公益广告 | N27: China | O27: 46318 | P27: 2026-Q4 | Q27: landslide | R27: 10 | S27: https://news.google.com/rss/articles/CBMiTEFVX3lxTE5jQUtRMEZxbjBPU3kxaVdvdjhRc09sV2NnalVMYklmVHFZQmwybkFHUjRLMVYtdzlvS3laVGlFMGw4aXhtdTduc1o4c3U?oc=5 | T27: =IF($B27="",0,IF(AND(OR(OR(Dashboard!$B$5="All themes",Dashboard!$B$5=""),$C27=Dashboard!$B$5),OR(OR(Dashboard!$G$5="All uses",Dashboard!$G$5=""),$E27=Dashboard!$G$5),N($D27)>=Lists!$H$2,OR(OR(Dashboard!$N$5="All windows",Dashboard!$N$5=""),$P27=Dashboard!$N$5)),1,0)) | U27: =IF($T27=1,N($D27)*1E14+MIN(MAX(N($R27),0),9999)*1E10+MIN(N($K27),99999)*1E5+99999-MIN(ROW(),99999),"")
A28: 25 | B28: What options exist for Mot Mountain in Quy Nhon: levelling it or preserving the historic site? | C28: Infrastructure & the Underground City | D28: 3 | E28: Feature lead | F28: To review | I28: What geotechnical and heritage considerations should guide levelling versus preserving a rocky hill site in an urban coastal city? | J28: Vietnam.vn | K28: 46319 | L28: Apa saja pilihan yang tersedia untuk Gunung Mot di Quy Nhon: meratakannya atau melestarikan situs bersejarah tersebut? | N28: Indonesia | O28: 46319 | P28: 2026-Q4 | R28: 6 | S28: https://news.google.com/rss/articles/CBMilgFBVV95cUxPbVV1NmdrOGFidElfXzZzV1ppbDBCOEc5V0luUWxOSTAwMXNGdmhVMkoxMjUwSUpmbU5lQlBuNkFVTXZGMk5IRzd5Y0taREt0ckRUT3VqSjBfbGFPTmRjUTZFS18wLTQ5Wi1ZdnFtYWd1QmN0U0Nsekx4ZzR0YVk0dmhhTXVpTW1rdEpCbGlKLTZNVXVzMEE?oc=5 | T28: =IF($B28="",0,IF(AND(OR(OR(Dashboard!$B$5="All themes",Dashboard!$B$5=""),$C28=Dashboard!$B$5),OR(OR(Dashboard!$G$5="All uses",Dashboard!$G$5=""),$E28=Dashboard!$G$5),N($D28)>=Lists!$H$2,OR(OR(Dashboard!$N$5="All windows",Dashboard!$N$5=""),$P28=Dashboard!$N$5)),1,0)) | U28: =IF($T28=1,N($D28)*1E14+MIN(MAX(N($R28),0),9999)*1E10+MIN(N($K28),99999)*1E5+99999-MIN(ROW(),99999),"")
A29: 26 | B29: At Khanh Le pass, vehicles are stopped in groups to face rockfall risk | C29: Hazards & Resilience | D29: 3 | E29: Regional insight | F29: To review | I29: How should rockfall risk on mountain roads be assessed and mitigated, and when is traffic control sufficient versus slope engineering? | J29: Vietnam.vn | K29: 46319 | L29: Au col de Khanh Le, les véhicules sont arrêtés par groupes pour faire face au risque de chutes de pierres. | N29: France | O29: 46317 | P29: 2026-Q4 | R29: 6 | S29: https://news.google.com/rss/articles/CBMihgFBVV95cUxPWEJjZzVNcHVub2RyNTNCN3huS0djNHpyQnA4YVJGdEtQSG9jTzdtMkRoR2lveGlsSmlZcmE0UGZsMVdnYThVT2phYU0zdjBoeDM1VkJlUUlGOUNQSmVoOFYyLVBRSF9manVQWW5jdUZsQThDUm5fU0J0NDBHT3VfV0lYNEwwdw?oc=5 | T29: =IF($B29="",0,IF(AND(OR(OR(Dashboard!$B$5="All themes",Dashboard!$B$5=""),$C29=Dashboard!$B$5),OR(OR(Dashboard!$G$5="All uses",Dashboard!$G$5=""),$E29=Dashboard!$G$5),N($D29)>=Lists!$H$2,OR(OR(Dashboard!$N$5="All windows",Dashboard!$N$5=""),$P29=Dashboard!$N$5)),1,0)) | U29: =IF($T29=1,N($D29)*1E14+MIN(MAX(N($R29),0),9999)*1E10+MIN(N($K29),99999)*1E5+99999-MIN(ROW(),99999),"")
A30: 27 | B30: Benjamin Banneker Middle School open following water main break, sinkhole repairs | C30: Infrastructure & the Underground City | D30: 3 | E30: News brief | F30: To review | I30: How do water main breaks undermine shallow soils and cause sinkholes, and what ground investigation would prevent school-site reopening delays? | J30: AOL.com | K30: 46319 | N30: United Kingdom | O30: 46317 | P30: 2026-Q4 | Q30: sinkhole | R30: 4 | S30: https://news.google.com/rss/articles/CBMihwFBVV95cUxQTm9rZVd2Tm9uUHpadkRIeXVwdkhhLTIyVjNESDJYOFBRWS1oUVlQaHRVVkE2cDJ6ekVwQ2pNRVZma25ySjJHQjU5ZHJMT0UtOHVCMnN5dlpJR2p2dUpzVXY5R2hkdFhFX2xBUlhQb1VCN3BxUEozeVJlek1pcWpDbkpheUxxcm8?oc=5 | T30: =IF($B30="",0,IF(AND(OR(OR(Dashboard!$B$5="All themes",Dashboard!$B$5=""),$C30=Dashboard!$B$5),OR(OR(Dashboard!$G$5="All uses",Dashboard!$G$5=""),$E30=Dashboard!$G$5),N($D30)>=Lists!$H$2,OR(OR(Dashboard!$N$5="All windows",Dashboard!$N$5=""),$P30=Dashboard!$N$5)),1,0)) | U30: =IF($T30=1,N($D30)*1E14+MIN(MAX(N($R30),0),9999)*1E10+MIN(N($K30),99999)*1E5+99999-MIN(ROW(),99999),"")
A31: 28 | B31: Landslide Derails Locomotive in Keralam, Train Services Restored | C31: Infrastructure & the Underground City | D31: 3 | E31: News brief | F31: To review | I31: What slope or embankment failure caused the locomotive derailment, and how should rail corridors be assessed for landslide risk? | J31: Deccan Chronicle | K31: 46319 | N31: Singapore | O31: 46317 | P31: 2026-Q4 | Q31: landslide | R31: 4 | S31: https://news.google.com/rss/articles/CBMiygFBVV95cUxPanNzOTkybjgybXo3ZDZ4R2psV2Zkd0VaTi05MWJOSFRkU1BQc29aZEpPQmtEMWUxNUgyUUlfbUt1XzZqa2swd2dESjVuU2lXUG1IVnk3VGIyM05LMzZHTjRyZmdlT0pYb3NGRDVLUXEyMkFrSF8ydWkwZG13ZlV6TGYzSFl4ZUZwQnVqajFPc3Rtc3VRYm1MUHhUUWVtUEJpOFFRVm1XeVV2bVlGMDBVTy1hNVlPTTRjQzd1bnJKUld3QVJRQlRwWVBn0gHKAUFVX3lxTE9qc3M5OTJuODJtejdkNnhHamxXZmR3RVpOLTkxYk5IVGRTUFBzb1pkSk9Ca0QxZTE1SDJRSV9tS3VfNmprazB3Z0RKNW5TaVdQbUhWeTdUYjIzTkszNkdONHJmZ2VPSlhvc0ZENUtRcTIyQWtIXzJ1aTBkbXdmVXpMZjNIWXhlRnBCdWpqMU9zdG1zdVFibUxQeFRRZW1QQmk4UVFWbVd5VXZtWUYwMFVPLWE1WU9NNGNDN3VuckpSV3dBUlFCVHBZUGc?oc=5 | T31: =IF($B31="",0,IF(AND(OR(OR(Dashboard!$B$5="All themes",Dashboard!$B$5=""),$C31=Dashboard!$B$5),OR(OR(Dashboard!$G$5="All uses",Dashboard!$G$5=""),$E31=Dashboard!$G$5),N($D31)>=Lists!$H$2,OR(OR(Dashboard!$N$5="All windows",Dashboard!$N$5=""),$P31=Dashboard!$N$5)),1,0)) | U31: =IF($T31=1,N($D31)*1E14+MIN(MAX(N($R31),0),9999)*1E10+MIN(N($K31),99999)*1E5+99999-MIN(ROW(),99999),"")
A32: 29 | B32: Gia Lai province People's Committee chairman discusses proposal to level Mot Mountain. | C32: Geotechnics & Society | D32: 3 | E32: Regional insight | F32: To review | I32: What are the geotechnical feasibility issues of levelling a hill, including rock quality, slope excavation and stability, compared with preservation? | J32: Vietnam.vn | K32: 46319 | L32: رئيس اللجنة الشعبية لمقاطعة جيا لاي يتحدث عن اقتراح تسوية جبل موت. | N32: Egypt | O32: 46318 | P32: 2026-Q4 | R32: 0 | S32: https://news.google.com/rss/articles/CBMijgFBVV95cUxNdzRhVnVlVUVUU1k4S3pUQVo2RFJENXlEM1V6Z2FrVzRMQ2cxb0pZNkJpWUY5UWFHd1ZIUEZmU2x4SGtydEtXN3k2bTBIYWQ3VmZNZkNTRkhfRFctd3JZdThkRW1HTWIxYmVXRDZsazFZVTJsUzVjTWk0R2FIUElZRG5lLUpaeXpHRlZSdFBn?oc=5 | T32: =IF($B32="",0,IF(AND(OR(OR(Dashboard!$B$5="All themes",Dashboard!$B$5=""),$C32=Dashboard!$B$5),OR(OR(Dashboard!$G$5="All uses",Dashboard!$G$5=""),$E32=Dashboard!$G$5),N($D32)>=Lists!$H$2,OR(OR(Dashboard!$N$5="All windows",Dashboard!$N$5=""),$P32=Dashboard!$N$5)),1,0)) | U32: =IF($T32=1,N($D32)*1E14+MIN(MAX(N($R32),0),9999)*1E10+MIN(N($K32),99999)*1E5+99999-MIN(ROW(),99999),"")
A33: 30 | B33: What are the options for Mot Mountain in Quy Nhon: level it or preserve the historic site? | C33: Geotechnics & Society | D33: 3 | E33: Regional insight | F33: To review | I33: What geotechnical assessments would be needed to compare levelling Mot Mountain with conserving its historic site, including rock stability and foundation implications? | J33: Vietnam.vn | K33: 46319 | L33: Quais são as opções para o Monte Mot em Quy Nhon: nivelá-lo ou preservar o sítio histórico? | N33: Brazil | O33: 46319 | P33: 2026-Q4 | R33: 0 | S33: https://news.google.com/rss/articles/CBMilgFBVV95cUxNS29sd2RXaDlmWXJYMzNQSnJKZGpCWmJpOE9kVEdWQ2RFcUd0UHBGdHdRczJLbFRwTHFDb0ZPY1lHOHNsRGtTLXhTb081eGdyWF9YcmcxZkFrc2VNNzBJOUxNU1ppYnZtWlZBTTlZcXNfa2xNVUZWRTUyMkRlTHRUMmJ4Nk95a1kybUNTTmVPaklQSHktWUE?oc=5 | T33: =IF($B33="",0,IF(AND(OR(OR(Dashboard!$B$5="All themes",Dashboard!$B$5=""),$C33=Dashboard!$B$5),OR(OR(Dashboard!$G$5="All uses",Dashboard!$G$5=""),$E33=Dashboard!$G$5),N($D33)>=Lists!$H$2,OR(OR(Dashboard!$N$5="All windows",Dashboard!$N$5=""),$P33=Dashboard!$N$5)),1,0)) | U33: =IF($T33=1,N($D33)*1E14+MIN(MAX(N($R33),0),9999)*1E10+MIN(N($K33),99999)*1E5+99999-MIN(ROW(),99999),"")

Sheet By theme
A1: Stories by theme | D1: ← Dashboard | E1: ↑ Start here | F1: Stories →
A2: Read-only view, best stories first. Click − / + in the margin on the left to collapse or expand a theme (or the 1 / 2 buttons for all). Status comes from the Stories sheet.
A4: Digital Geotechnics · 1 story · 1 rated 5 / 5 · 0 feature leads
A5: No. | B5: Relevance | C5: Headline | D5: Link | E5: Suggested use | F5: Status | G5: Source | H5: Digest | I5: Magazine angle / summary
A6: 1 | B6: 5 | C6: Automatic segmentation of rock mass fracture networks from UAV imagery using cross-domain transfer learning under scarce labels. | D6: Open article | E6: Academia-to-Industry topic | F6: =IFERROR(INDEX(Stories!$F$4:$F$33,MATCH($A6,Stories!$A$4:$A$33,0))&"","") | G6: 生物通 | H6: 46319 | I6: Can transfer learning from related image domains reliably segment rock fracture networks in UAV imagery when labelled data are scarce, and how accurate are the results?
A8: Hazards & Resilience · 18 stories · 0 rated 5 / 5 · 6 feature leads
A9: No. | B9: Relevance | C9: Headline | D9: Link | E9: Suggested use | F9: Status | G9: Source | H9: Digest | I9: Magazine angle / summary
A10: 2 | B10: 4 | C10: Landslide-prevention embankment threatens residential area | D10: Open article | E10: Feature lead | F10: =IFERROR(INDEX(Stories!$F$4:$F$33,MATCH($A10,Stories!$A$4:$A$33,0))&"","") | G10: Vietnam.vn | H10: 46319 | I10: Can retaining and protective embankments be designed to resist landslide loading from upslope slopes beside settlements, and how should such risk be assessed?
A11: 3 | B11: 4 | C11: Storms in Liguria, major landslide in Savona: the collapse destroyed a city road | D11: Open article | E11: News brief | F11: =IFERROR(INDEX(Stories!$F$4:$F$33,MATCH($A11,Stories!$A$4:$A$33,0))&"","") | G11: agenzia giornalistica opinione | H11: 46319 | I11: What triggered this large rock or soil slope failure in Savona during heavy rain, and what does the collapse reveal about slope stability in Liguria?
A12: 4 | B12: 4 | C12: At Khanh Le pass, traffic will be interrupted at 30-minute intervals to deal with landslides; road users should plan accordingly | D12: Open article | E12: Feature lead | F12: =IFERROR(INDEX(Stories!$F$4:$F$33,MATCH($A12,Stories!$A$4:$A$33,0))&"","") | G12: Vietnam.vn | H12: 46319 | I12: How should traffic management and monitoring be combined with slope stabilisation on mountain passes subject to recurrent landslides?
A13: 5 | B13: 4 | C13: Valmontone, bad weather: tuff slope collapses onto Prenestina road, road partially closed | D13: Open article | E13: News brief | F13: =IFERROR(INDEX(Stories!$F$4:$F$33,MATCH($A13,Stories!$A$4:$A$33,0))&"","") | G13: Il Giornale dei Castelli Romani | H13: 46319 | I13: What causes tuff cliff collapse in volcanic deposits under rainfall, and how can such slopes be assessed and stabilised near roads?
A14: 6 | B14: 4 | C14: Bonea, landslide in Capo locality: mayor closes three roads by urgent order | D14: Open article | E14: News brief | F14: =IFERROR(INDEX(Stories!$F$4:$F$33,MATCH($A14,Stories!$A$4:$A$33,0))&"","") | G14: Tv7 Benevento | H14: 46319 | I14: What ground investigation would confirm the landslide mechanism at Capo locality and guide safe reopening of the three closed roads?
A15: 7 | B15: 4 | C15: La frana del Cencione Tra fango e polemiche Le ruspe sono al lavoro | D15: Open article | E15: Feature lead | F15: =IFERROR(INDEX(Stories!$F$4:$F$33,MATCH($A15,Stories!$A$4:$A$33,0))&"","") | G15: Zazoom Social News | H15: 46319 | I15: How should authorities balance urgent earthworks with geotechnical investigation and accountability when a landslide site becomes politically contested?
